2018-08-10 11:38:41,642 - exception.py[line:135] - ERROR: Internal Server Error: /stormwindcity/api/freessl/login/
Traceback (most recent call last):
  File "/root/Envs/TS/lib/python3.5/site-packages/django/core/handlers/exception.py", line 41, in inner
    response = get_response(request)
  File "/root/Envs/TS/lib/python3.5/site-packages/django/core/handlers/base.py", line 217, in _get_response
    response = self.process_exception_by_middleware(e, request)
  File "/root/Envs/TS/lib/python3.5/site-packages/django/core/handlers/base.py", line 215, in _get_response
    response = response.render()
  File "/root/Envs/TS/lib/python3.5/site-packages/django/template/response.py", line 107, in render
    self.content = self.rendered_content
  File "/root/Envs/TS/lib/python3.5/site-packages/rest_framework/response.py", line 57, in rendered_content
    assert renderer, ".accepted_renderer not set on Response"
AssertionError: .accepted_renderer not set on Response
2018-08-10 11:38:43,334 - exception.py[line:135] - ERROR: Internal Server Error: /stormwindcity/api/freessl/login/
Traceback (most recent call last):
  File "/root/Envs/TS/lib/python3.5/site-packages/django/core/handlers/exception.py", line 41, in inner
    response = get_response(request)
  File "/root/Envs/TS/lib/python3.5/site-packages/django/core/handlers/base.py", line 217, in _get_response
    response = self.process_exception_by_middleware(e, request)
  File "/root/Envs/TS/lib/python3.5/site-packages/django/core/handlers/base.py", line 215, in _get_response
    response = response.render()
  File "/root/Envs/TS/lib/python3.5/site-packages/django/template/response.py", line 107, in render
    self.content = self.rendered_content
  File "/root/Envs/TS/lib/python3.5/site-packages/rest_framework/response.py", line 57, in rendered_content
    assert renderer, ".accepted_renderer not set on Response"
AssertionError: .accepted_renderer not set on Response
2018-08-10 11:40:24,746 - exception.py[line:135] - ERROR: Internal Server Error: /stormwindcity/api/freessl/create_order/
Traceback (most recent call last):
  File "/root/Envs/TS/lib/python3.5/site-packages/django/core/handlers/exception.py", line 41, in inner
    response = get_response(request)
  File "/root/Envs/TS/lib/python3.5/site-packages/django/core/handlers/base.py", line 187, in _get_response
    response = self.process_exception_by_middleware(e, request)
  File "/root/Envs/TS/lib/python3.5/site-packages/django/core/handlers/base.py", line 185, in _get_response
    response = wrapped_callback(request, *callback_args, **callback_kwargs)
  File "/opt/TS/StormwindCity/views.py", line 55, in TrustAsia_apply_create_order
    domain = request.body.decode()['domain']
TypeError: string indices must be integers
2018-08-10 11:43:28,485 - base.py[line:152] - WARNING: Not Found: /accounts/login/
2018-08-10 11:53:10,586 - exception.py[line:135] - ERROR: Internal Server Error: /stormwindcity/api/freessl/cert_list/
Traceback (most recent call last):
  File "/root/Envs/TS/lib/python3.5/site-packages/django/core/handlers/exception.py", line 41, in inner
    response = get_response(request)
  File "/root/Envs/TS/lib/python3.5/site-packages/django/core/handlers/base.py", line 187, in _get_response
    response = self.process_exception_by_middleware(e, request)
  File "/root/Envs/TS/lib/python3.5/site-packages/django/core/handlers/base.py", line 185, in _get_response
    response = wrapped_callback(request, *callback_args, **callback_kwargs)
  File "/opt/TS/StormwindCity/views.py", line 187, in TrustAsia_cert_list
    certList = TrustAsia_obj.Cert_list()
  File "/opt/TS/StormwindCity/FreeSSL.py", line 97, in Cert_list
    return_value = json.loads(response.text)
  File "/usr/local/python3/lib/python3.5/json/__init__.py", line 319, in loads
    return _default_decoder.decode(s)
  File "/usr/local/python3/lib/python3.5/json/decoder.py", line 342, in decode
    raise JSONDecodeError("Extra data", s, end)
json.decoder.JSONDecodeError: Extra data: line 1 column 5 (char 4)
2018-08-10 11:53:15,310 - exception.py[line:135] - ERROR: Internal Server Error: /stormwindcity/api/freessl/cert_list/
Traceback (most recent call last):
  File "/root/Envs/TS/lib/python3.5/site-packages/django/core/handlers/exception.py", line 41, in inner
    response = get_response(request)
  File "/root/Envs/TS/lib/python3.5/site-packages/django/core/handlers/base.py", line 187, in _get_response
    response = self.process_exception_by_middleware(e, request)
  File "/root/Envs/TS/lib/python3.5/site-packages/django/core/handlers/base.py", line 185, in _get_response
    response = wrapped_callback(request, *callback_args, **callback_kwargs)
  File "/opt/TS/StormwindCity/views.py", line 187, in TrustAsia_cert_list
    certList = TrustAsia_obj.Cert_list()
  File "/opt/TS/StormwindCity/FreeSSL.py", line 97, in Cert_list
    return_value = json.loads(response.text)
  File "/usr/local/python3/lib/python3.5/json/__init__.py", line 319, in loads
    return _default_decoder.decode(s)
  File "/usr/local/python3/lib/python3.5/json/decoder.py", line 342, in decode
    raise JSONDecodeError("Extra data", s, end)
json.decoder.JSONDecodeError: Extra data: line 1 column 5 (char 4)
2018-08-10 11:55:06,072 - exception.py[line:135] - ERROR: Internal Server Error: /stormwindcity/api/freessl/cert_list/
Traceback (most recent call last):
  File "/root/Envs/TS/lib/python3.5/site-packages/django/core/handlers/exception.py", line 41, in inner
    response = get_response(request)
  File "/root/Envs/TS/lib/python3.5/site-packages/django/core/handlers/base.py", line 187, in _get_response
    response = self.process_exception_by_middleware(e, request)
  File "/root/Envs/TS/lib/python3.5/site-packages/django/core/handlers/base.py", line 185, in _get_response
    response = wrapped_callback(request, *callback_args, **callback_kwargs)
  File "/opt/TS/StormwindCity/views.py", line 187, in TrustAsia_cert_list
    certList = TrustAsia_obj.Cert_list()
  File "/opt/TS/StormwindCity/FreeSSL.py", line 97, in Cert_list
    return_value = json.loads(response.text)
  File "/usr/local/python3/lib/python3.5/json/__init__.py", line 319, in loads
    return _default_decoder.decode(s)
  File "/usr/local/python3/lib/python3.5/json/decoder.py", line 342, in decode
    raise JSONDecodeError("Extra data", s, end)
json.decoder.JSONDecodeError: Extra data: line 1 column 5 (char 4)
2018-08-10 11:58:12,827 - exception.py[line:135] - ERROR: Internal Server Error: /stormwindcity/api/freessl/cert_list/
Traceback (most recent call last):
  File "/root/Envs/TS/lib/python3.5/site-packages/django/core/handlers/exception.py", line 41, in inner
    response = get_response(request)
  File "/root/Envs/TS/lib/python3.5/site-packages/django/core/handlers/base.py", line 187, in _get_response
    response = self.process_exception_by_middleware(e, request)
  File "/root/Envs/TS/lib/python3.5/site-packages/django/core/handlers/base.py", line 185, in _get_response
    response = wrapped_callback(request, *callback_args, **callback_kwargs)
  File "/opt/TS/StormwindCity/views.py", line 187, in TrustAsia_cert_list
    certList = TrustAsia_obj.Cert_list()
  File "/opt/TS/StormwindCity/FreeSSL.py", line 98, in Cert_list
    return_value = json.loads(response.text)
  File "/usr/local/python3/lib/python3.5/json/__init__.py", line 319, in loads
    return _default_decoder.decode(s)
  File "/usr/local/python3/lib/python3.5/json/decoder.py", line 342, in decode
    raise JSONDecodeError("Extra data", s, end)
json.decoder.JSONDecodeError: Extra data: line 1 column 5 (char 4)
2018-08-10 16:56:49,741 - base.py[line:152] - WARNING: Not Found: /spiderkingdom/api/cdn/
2018-08-10 16:56:53,953 - base.py[line:152] - WARNING: Not Found: /spiderkingdom/api/cnd/
2018-08-10 16:56:54,098 - base.py[line:152] - WARNING: Not Found: /favicon.ico
2018-08-10 16:57:04,849 - base.py[line:152] - WARNING: Not Found: /spiderkingdom/api/cdn/
2018-08-10 18:04:07,909 - base.py[line:152] - WARNING: Not Found: /spiderkingdom/api/domains/1/
2018-08-10 18:04:13,236 - base.py[line:152] - WARNING: Not Found: /spiderkingdom/api/domains/2/
2018-08-10 18:04:17,347 - base.py[line:152] - WARNING: Not Found: /spiderkingdom/api/domains/3/
2018-08-10 18:05:14,959 - base.py[line:152] - WARNING: Not Found: /spiderkingdom/api/domains/ju888.net/
2018-08-10 18:05:22,845 - base.py[line:152] - WARNING: Not Found: /spiderkingdom/api/domains/iju888.net/
2018-08-10 18:29:18,151 - base.py[line:152] - WARNING: Not Found: /spiderkingdom/api/cdn/
2018-08-11 08:54:56,402 - base.py[line:152] - WARNING: Not Found: /favicon.ico
2018-08-11 10:05:28,750 - base.py[line:152] - WARNING: Not Found: /spiderkingdom/api/domains/1/
2018-08-11 10:16:30,782 - exception.py[line:135] - ERROR: Internal Server Error: /spiderkingdom/api/chart/1/
Traceback (most recent call last):
  File "/root/Envs/TS/lib/python3.5/site-packages/django/core/handlers/exception.py", line 41, in inner
    response = get_response(request)
  File "/root/Envs/TS/lib/python3.5/site-packages/django/core/handlers/base.py", line 187, in _get_response
    response = self.process_exception_by_middleware(e, request)
  File "/root/Envs/TS/lib/python3.5/site-packages/django/core/handlers/base.py", line 185, in _get_response
    response = wrapped_callback(request, *callback_args, **callback_kwargs)
  File "/root/Envs/TS/lib/python3.5/site-packages/django/views/decorators/csrf.py", line 58, in wrapped_view
    return view_func(*args, **kwargs)
  File "/root/Envs/TS/lib/python3.5/site-packages/rest_framework/viewsets.py", line 103, in view
    return self.dispatch(request, *args, **kwargs)
  File "/root/Envs/TS/lib/python3.5/site-packages/rest_framework/views.py", line 483, in dispatch
    response = self.handle_exception(exc)
  File "/root/Envs/TS/lib/python3.5/site-packages/rest_framework/views.py", line 443, in handle_exception
    self.raise_uncaught_exception(exc)
  File "/root/Envs/TS/lib/python3.5/site-packages/rest_framework/views.py", line 480, in dispatch
    response = handler(request, *args, **kwargs)
  File "/opt/TS/SpiderKingdom/views.py", line 101, in list
    domain_obj = models.Domain.objects.get(id=kwargs.get("domain_id"))
  File "/root/Envs/TS/lib/python3.5/site-packages/django/db/models/manager.py", line 85, in manager_method
    return getattr(self.get_queryset(), name)(*args, **kwargs)
  File "/root/Envs/TS/lib/python3.5/site-packages/django/db/models/query.py", line 379, in get
    self.model._meta.object_name
SpiderKingdom.models.DoesNotExist: Domain matching query does not exist.
2018-08-11 10:27:18,822 - exception.py[line:135] - ERROR: Internal Server Error: /spiderkingdom/api/chart/2/
Traceback (most recent call last):
  File "/root/Envs/TS/lib/python3.5/site-packages/django/core/handlers/exception.py", line 41, in inner
    response = get_response(request)
  File "/root/Envs/TS/lib/python3.5/site-packages/django/core/handlers/base.py", line 187, in _get_response
    response = self.process_exception_by_middleware(e, request)
  File "/root/Envs/TS/lib/python3.5/site-packages/django/core/handlers/base.py", line 185, in _get_response
    response = wrapped_callback(request, *callback_args, **callback_kwargs)
  File "/root/Envs/TS/lib/python3.5/site-packages/django/views/decorators/csrf.py", line 58, in wrapped_view
    return view_func(*args, **kwargs)
  File "/root/Envs/TS/lib/python3.5/site-packages/rest_framework/viewsets.py", line 103, in view
    return self.dispatch(request, *args, **kwargs)
  File "/root/Envs/TS/lib/python3.5/site-packages/rest_framework/views.py", line 483, in dispatch
    response = self.handle_exception(exc)
  File "/root/Envs/TS/lib/python3.5/site-packages/rest_framework/views.py", line 443, in handle_exception
    self.raise_uncaught_exception(exc)
  File "/root/Envs/TS/lib/python3.5/site-packages/rest_framework/views.py", line 480, in dispatch
    response = handler(request, *args, **kwargs)
  File "/opt/TS/SpiderKingdom/views.py", line 101, in list
    domain_obj = models.Domain.objects.get(id=kwargs.get("domain_id"))
  File "/root/Envs/TS/lib/python3.5/site-packages/django/db/models/manager.py", line 85, in manager_method
    return getattr(self.get_queryset(), name)(*args, **kwargs)
  File "/root/Envs/TS/lib/python3.5/site-packages/django/db/models/query.py", line 379, in get
    self.model._meta.object_name
SpiderKingdom.models.DoesNotExist: Domain matching query does not exist.
2018-08-11 11:10:40,274 - base.py[line:152] - WARNING: Not Found: /spiderkingdom/api/nodes/1
2018-08-11 11:10:51,783 - base.py[line:152] - WARNING: Not Found: /spiderkingdom/api/nodes/1/
2018-08-11 11:11:01,773 - base.py[line:152] - WARNING: Not Found: /spiderkingdom/api/nodes/2/
2018-08-11 11:11:05,236 - base.py[line:152] - WARNING: Not Found: /spiderkingdom/api/nodes/4/
2018-08-11 11:11:47,990 - base.py[line:152] - WARNING: Not Found: /spiderkingdom/api/nodes/2/
2018-08-11 11:25:26,482 - base.py[line:152] - WARNING: Not Found: /spiderkingdom/api/projects/1/
2018-08-11 13:11:49,205 - base.py[line:152] - WARNING: Not Found: /stormwindcity/api/
2018-08-11 13:12:07,619 - base.py[line:152] - WARNING: Not Found: /stormwindcity/api/
2018-08-11 13:12:15,215 - base.py[line:152] - WARNING: Not Found: /stormwindcity/api/freessl、
2018-08-11 13:12:25,676 - base.py[line:152] - WARNING: Not Found: /stormwindcity/api/
2018-08-11 13:56:23,153 - exception.py[line:135] - ERROR: Internal Server Error: /stormwindcity/api/freessl/order_detail/
Traceback (most recent call last):
  File "/root/Envs/TS/lib/python3.5/site-packages/django/core/handlers/exception.py", line 41, in inner
    response = get_response(request)
  File "/root/Envs/TS/lib/python3.5/site-packages/django/core/handlers/base.py", line 187, in _get_response
    response = self.process_exception_by_middleware(e, request)
  File "/root/Envs/TS/lib/python3.5/site-packages/django/core/handlers/base.py", line 185, in _get_response
    response = wrapped_callback(request, *callback_args, **callback_kwargs)
  File "/opt/TS/StormwindCity/views.py", line 213, in TrustAsia_order_detail
    orderDetail = TrustAsia_obj.Orders_detail(order_id)
  File "/opt/TS/StormwindCity/FreeSSL.py", line 70, in Orders_detail
    response = self.requests.get("orders/detail/" + order_id,headers=self.headers)
TypeError: Can't convert 'NoneType' object to str implicitly
2018-08-11 13:57:29,400 - exception.py[line:135] - ERROR: Internal Server Error: /stormwindcity/api/freessl/order_detail/
Traceback (most recent call last):
  File "/root/Envs/TS/lib/python3.5/site-packages/django/core/handlers/exception.py", line 41, in inner
    response = get_response(request)
  File "/root/Envs/TS/lib/python3.5/site-packages/django/core/handlers/base.py", line 187, in _get_response
    response = self.process_exception_by_middleware(e, request)
  File "/root/Envs/TS/lib/python3.5/site-packages/django/core/handlers/base.py", line 185, in _get_response
    response = wrapped_callback(request, *callback_args, **callback_kwargs)
  File "/opt/TS/StormwindCity/views.py", line 213, in TrustAsia_order_detail
    orderDetail = TrustAsia_obj.Orders_detail(order_id)
  File "/opt/TS/StormwindCity/FreeSSL.py", line 70, in Orders_detail
    response = self.requests.get("orders/detail/" + order_id,headers=self.headers)
TypeError: Can't convert 'NoneType' object to str implicitly
2018-08-11 13:58:16,964 - exception.py[line:135] - ERROR: Internal Server Error: /stormwindcity/api/freessl/order_detail/
Traceback (most recent call last):
  File "/root/Envs/TS/lib/python3.5/site-packages/django/core/handlers/exception.py", line 41, in inner
    response = get_response(request)
  File "/root/Envs/TS/lib/python3.5/site-packages/django/core/handlers/base.py", line 187, in _get_response
    response = self.process_exception_by_middleware(e, request)
  File "/root/Envs/TS/lib/python3.5/site-packages/django/core/handlers/base.py", line 185, in _get_response
    response = wrapped_callback(request, *callback_args, **callback_kwargs)
  File "/opt/TS/StormwindCity/views.py", line 213, in TrustAsia_order_detail
    orderDetail = TrustAsia_obj.Orders_detail(order_id)
  File "/opt/TS/StormwindCity/FreeSSL.py", line 70, in Orders_detail
    response = self.requests.get("orders/detail/" + order_id,headers=self.headers)
TypeError: Can't convert 'NoneType' object to str implicitly
2018-08-11 13:58:49,819 - exception.py[line:135] - ERROR: Internal Server Error: /stormwindcity/api/freessl/order_detail/
Traceback (most recent call last):
  File "/root/Envs/TS/lib/python3.5/site-packages/django/core/handlers/exception.py", line 41, in inner
    response = get_response(request)
  File "/root/Envs/TS/lib/python3.5/site-packages/django/core/handlers/base.py", line 198, in _get_response
    "returned None instead." % (callback.__module__, view_name)
ValueError: The view StormwindCity.views.TrustAsia_order_detail didn't return an HttpResponse object. It returned None instead.
2018-08-11 14:00:19,336 - exception.py[line:135] - ERROR: Internal Server Error: /stormwindcity/api/freessl/order_detail/
Traceback (most recent call last):
  File "/root/Envs/TS/lib/python3.5/site-packages/django/core/handlers/exception.py", line 41, in inner
    response = get_response(request)
  File "/root/Envs/TS/lib/python3.5/site-packages/django/core/handlers/base.py", line 187, in _get_response
    response = self.process_exception_by_middleware(e, request)
  File "/root/Envs/TS/lib/python3.5/site-packages/django/core/handlers/base.py", line 185, in _get_response
    response = wrapped_callback(request, *callback_args, **callback_kwargs)
  File "/opt/TS/StormwindCity/views.py", line 213, in TrustAsia_order_detail
    orderDetail = TrustAsia_obj.Orders_detail(order_id)
  File "/opt/TS/StormwindCity/FreeSSL.py", line 70, in Orders_detail
    response = self.requests.get("orders/detail/" + order_id,headers=self.headers)
TypeError: Can't convert 'NoneType' object to str implicitly
2018-08-11 14:01:27,305 - exception.py[line:135] - ERROR: Internal Server Error: /stormwindcity/api/freessl/order_detail/
Traceback (most recent call last):
  File "/root/Envs/TS/lib/python3.5/site-packages/django/core/handlers/exception.py", line 41, in inner
    response = get_response(request)
  File "/root/Envs/TS/lib/python3.5/site-packages/django/core/handlers/base.py", line 187, in _get_response
    response = self.process_exception_by_middleware(e, request)
  File "/root/Envs/TS/lib/python3.5/site-packages/django/core/handlers/base.py", line 185, in _get_response
    response = wrapped_callback(request, *callback_args, **callback_kwargs)
  File "/opt/TS/StormwindCity/views.py", line 213, in TrustAsia_order_detail
    orderDetail = TrustAsia_obj.Orders_detail(order_id)
  File "/opt/TS/StormwindCity/FreeSSL.py", line 70, in Orders_detail
    response = self.requests.get("orders/detail/" + order_id,headers=self.headers)
TypeError: Can't convert 'NoneType' object to str implicitly
2018-08-11 14:03:34,452 - exception.py[line:135] - ERROR: Internal Server Error: /stormwindcity/api/freessl/order_detail/
Traceback (most recent call last):
  File "/root/Envs/TS/lib/python3.5/site-packages/django/core/handlers/exception.py", line 41, in inner
    response = get_response(request)
  File "/root/Envs/TS/lib/python3.5/site-packages/django/core/handlers/base.py", line 187, in _get_response
    response = self.process_exception_by_middleware(e, request)
  File "/root/Envs/TS/lib/python3.5/site-packages/django/core/handlers/base.py", line 185, in _get_response
    response = wrapped_callback(request, *callback_args, **callback_kwargs)
  File "/opt/TS/StormwindCity/views.py", line 215, in TrustAsia_order_detail
    orderDetail = TrustAsia_obj.Orders_detail(order_id)
  File "/opt/TS/StormwindCity/FreeSSL.py", line 70, in Orders_detail
    response = self.requests.get("orders/detail/" + order_id,headers=self.headers)
TypeError: Can't convert 'NoneType' object to str implicitly
2018-08-11 14:04:14,010 - exception.py[line:135] - ERROR: Internal Server Error: /stormwindcity/api/freessl/order_detail/
Traceback (most recent call last):
  File "/root/Envs/TS/lib/python3.5/site-packages/django/core/handlers/exception.py", line 41, in inner
    response = get_response(request)
  File "/root/Envs/TS/lib/python3.5/site-packages/django/core/handlers/base.py", line 187, in _get_response
    response = self.process_exception_by_middleware(e, request)
  File "/root/Envs/TS/lib/python3.5/site-packages/django/core/handlers/base.py", line 185, in _get_response
    response = wrapped_callback(request, *callback_args, **callback_kwargs)
  File "/opt/TS/StormwindCity/views.py", line 212, in TrustAsia_order_detail
    order_id = request.body.decode()['order_id']
TypeError: string indices must be integers
2018-08-11 14:05:51,800 - exception.py[line:135] - ERROR: Internal Server Error: /stormwindcity/api/freessl/create_order/
Traceback (most recent call last):
  File "/root/Envs/TS/lib/python3.5/site-packages/django/core/handlers/exception.py", line 41, in inner
    response = get_response(request)
  File "/root/Envs/TS/lib/python3.5/site-packages/django/core/handlers/base.py", line 187, in _get_response
    response = self.process_exception_by_middleware(e, request)
  File "/root/Envs/TS/lib/python3.5/site-packages/django/core/handlers/base.py", line 185, in _get_response
    response = wrapped_callback(request, *callback_args, **callback_kwargs)
  File "/opt/TS/StormwindCity/views.py", line 57, in TrustAsia_apply_create_order
    domain = request.body.decode()['domain']
TypeError: string indices must be integers
2018-08-11 14:09:31,317 - exception.py[line:135] - ERROR: Internal Server Error: /stormwindcity/api/freessl/order_detail/
Traceback (most recent call last):
  File "/root/Envs/TS/lib/python3.5/site-packages/django/core/handlers/exception.py", line 41, in inner
    response = get_response(request)
  File "/root/Envs/TS/lib/python3.5/site-packages/django/core/handlers/base.py", line 187, in _get_response
    response = self.process_exception_by_middleware(e, request)
  File "/root/Envs/TS/lib/python3.5/site-packages/django/core/handlers/base.py", line 185, in _get_response
    response = wrapped_callback(request, *callback_args, **callback_kwargs)
  File "/opt/TS/StormwindCity/views.py", line 214, in TrustAsia_order_detail
    orderDetail = TrustAsia_obj.Orders_detail(order_id['order_id'])
TypeError: string indices must be integers
2018-08-11 14:10:10,637 - exception.py[line:135] - ERROR: Internal Server Error: /stormwindcity/api/freessl/order_detail/
Traceback (most recent call last):
  File "/root/Envs/TS/lib/python3.5/site-packages/django/core/handlers/exception.py", line 41, in inner
    response = get_response(request)
  File "/root/Envs/TS/lib/python3.5/site-packages/django/core/handlers/base.py", line 187, in _get_response
    response = self.process_exception_by_middleware(e, request)
  File "/root/Envs/TS/lib/python3.5/site-packages/django/core/handlers/base.py", line 185, in _get_response
    response = wrapped_callback(request, *callback_args, **callback_kwargs)
  File "/opt/TS/StormwindCity/views.py", line 214, in TrustAsia_order_detail
    orderDetail = TrustAsia_obj.Orders_detail(order_id['order_id'])
TypeError: string indices must be integers
2018-08-11 14:11:47,929 - exception.py[line:135] - ERROR: Internal Server Error: /stormwindcity/api/freessl/order_detail/
Traceback (most recent call last):
  File "/root/Envs/TS/lib/python3.5/site-packages/django/core/handlers/exception.py", line 41, in inner
    response = get_response(request)
  File "/root/Envs/TS/lib/python3.5/site-packages/django/core/handlers/base.py", line 187, in _get_response
    response = self.process_exception_by_middleware(e, request)
  File "/root/Envs/TS/lib/python3.5/site-packages/django/core/handlers/base.py", line 185, in _get_response
    response = wrapped_callback(request, *callback_args, **callback_kwargs)
  File "/opt/TS/StormwindCity/views.py", line 214, in TrustAsia_order_detail
    orderDetail = TrustAsia_obj.Orders_detail(order_id['order_id'])
TypeError: string indices must be integers
2018-08-11 14:20:30,654 - exception.py[line:135] - ERROR: Internal Server Error: /stormwindcity/api/freessl/create_order/
Traceback (most recent call last):
  File "/root/Envs/TS/lib/python3.5/site-packages/django/core/handlers/exception.py", line 41, in inner
    response = get_response(request)
  File "/root/Envs/TS/lib/python3.5/site-packages/django/core/handlers/base.py", line 187, in _get_response
    response = self.process_exception_by_middleware(e, request)
  File "/root/Envs/TS/lib/python3.5/site-packages/django/core/handlers/base.py", line 185, in _get_response
    response = wrapped_callback(request, *callback_args, **callback_kwargs)
  File "/opt/TS/StormwindCity/views.py", line 57, in TrustAsia_apply_create_order
    domain = request.body.decode()['domain']
TypeError: string indices must be integers
2018-08-11 17:42:40,017 - exception.py[line:135] - ERROR: Internal Server Error: /stormwindcity/api/freessl/order_detail/
Traceback (most recent call last):
  File "/root/Envs/TS/lib/python3.5/site-packages/django/core/handlers/exception.py", line 41, in inner
    response = get_response(request)
  File "/root/Envs/TS/lib/python3.5/site-packages/django/core/handlers/base.py", line 187, in _get_response
    response = self.process_exception_by_middleware(e, request)
  File "/root/Envs/TS/lib/python3.5/site-packages/django/core/handlers/base.py", line 185, in _get_response
    response = wrapped_callback(request, *callback_args, **callback_kwargs)
  File "/opt/TS/StormwindCity/views.py", line 214, in TrustAsia_order_detail
    orderDetail = TrustAsia_obj.Orders_detail(order_id['order_id'])
TypeError: string indices must be integers
2018-08-11 17:46:04,926 - exception.py[line:135] - ERROR: Internal Server Error: /stormwindcity/api/freessl/order_detail/
Traceback (most recent call last):
  File "/root/Envs/TS/lib/python3.5/site-packages/django/core/handlers/exception.py", line 41, in inner
    response = get_response(request)
  File "/root/Envs/TS/lib/python3.5/site-packages/django/core/handlers/base.py", line 187, in _get_response
    response = self.process_exception_by_middleware(e, request)
  File "/root/Envs/TS/lib/python3.5/site-packages/django/core/handlers/base.py", line 185, in _get_response
    response = wrapped_callback(request, *callback_args, **callback_kwargs)
  File "/opt/TS/StormwindCity/views.py", line 214, in TrustAsia_order_detail
    orderDetail = TrustAsia_obj.Orders_detail(order_id['order_id'])
TypeError: string indices must be integers
2018-08-11 17:47:32,304 - exception.py[line:135] - ERROR: Internal Server Error: /stormwindcity/api/freessl/order_detail/
Traceback (most recent call last):
  File "/root/Envs/TS/lib/python3.5/site-packages/django/core/handlers/exception.py", line 41, in inner
    response = get_response(request)
  File "/root/Envs/TS/lib/python3.5/site-packages/django/core/handlers/base.py", line 187, in _get_response
    response = self.process_exception_by_middleware(e, request)
  File "/root/Envs/TS/lib/python3.5/site-packages/django/core/handlers/base.py", line 185, in _get_response
    response = wrapped_callback(request, *callback_args, **callback_kwargs)
  File "/opt/TS/StormwindCity/views.py", line 214, in TrustAsia_order_detail
    orderDetail = TrustAsia_obj.Orders_detail(order_id['order_id'])
TypeError: string indices must be integers
2018-08-11 17:48:29,432 - exception.py[line:135] - ERROR: Internal Server Error: /stormwindcity/api/freessl/create_order/
Traceback (most recent call last):
  File "/root/Envs/TS/lib/python3.5/site-packages/django/core/handlers/exception.py", line 41, in inner
    response = get_response(request)
  File "/root/Envs/TS/lib/python3.5/site-packages/django/core/handlers/base.py", line 187, in _get_response
    response = self.process_exception_by_middleware(e, request)
  File "/root/Envs/TS/lib/python3.5/site-packages/django/core/handlers/base.py", line 185, in _get_response
    response = wrapped_callback(request, *callback_args, **callback_kwargs)
  File "/opt/TS/StormwindCity/views.py", line 57, in TrustAsia_apply_create_order
    domain = request.body.decode()['domain']
TypeError: string indices must be integers
2018-08-11 17:50:18,416 - exception.py[line:135] - ERROR: Internal Server Error: /stormwindcity/api/freessl/create_order/
Traceback (most recent call last):
  File "/root/Envs/TS/lib/python3.5/site-packages/django/core/handlers/exception.py", line 41, in inner
    response = get_response(request)
  File "/root/Envs/TS/lib/python3.5/site-packages/django/core/handlers/base.py", line 187, in _get_response
    response = self.process_exception_by_middleware(e, request)
  File "/root/Envs/TS/lib/python3.5/site-packages/django/core/handlers/base.py", line 185, in _get_response
    response = wrapped_callback(request, *callback_args, **callback_kwargs)
  File "/opt/TS/StormwindCity/views.py", line 57, in TrustAsia_apply_create_order
    domain = json.loads(request.body.decode()['domain'])
TypeError: string indices must be integers
2018-08-11 17:50:26,228 - exception.py[line:135] - ERROR: Internal Server Error: /stormwindcity/api/freessl/create_order/
Traceback (most recent call last):
  File "/root/Envs/TS/lib/python3.5/site-packages/django/core/handlers/exception.py", line 41, in inner
    response = get_response(request)
  File "/root/Envs/TS/lib/python3.5/site-packages/django/core/handlers/base.py", line 187, in _get_response
    response = self.process_exception_by_middleware(e, request)
  File "/root/Envs/TS/lib/python3.5/site-packages/django/core/handlers/base.py", line 185, in _get_response
    response = wrapped_callback(request, *callback_args, **callback_kwargs)
  File "/opt/TS/StormwindCity/views.py", line 57, in TrustAsia_apply_create_order
    domain = json.loads(request.body.decode()['domain'])
TypeError: string indices must be integers
2018-08-11 17:50:35,032 - exception.py[line:135] - ERROR: Internal Server Error: /stormwindcity/api/freessl/create_order/
Traceback (most recent call last):
  File "/root/Envs/TS/lib/python3.5/site-packages/django/core/handlers/exception.py", line 41, in inner
    response = get_response(request)
  File "/root/Envs/TS/lib/python3.5/site-packages/django/core/handlers/base.py", line 187, in _get_response
    response = self.process_exception_by_middleware(e, request)
  File "/root/Envs/TS/lib/python3.5/site-packages/django/core/handlers/base.py", line 185, in _get_response
    response = wrapped_callback(request, *callback_args, **callback_kwargs)
  File "/opt/TS/StormwindCity/views.py", line 57, in TrustAsia_apply_create_order
    domain = json.loads(request.body.decode()['domain'])
TypeError: string indices must be integers
2018-08-11 17:51:03,733 - exception.py[line:135] - ERROR: Internal Server Error: /stormwindcity/api/freessl/order_authz/
Traceback (most recent call last):
  File "/root/Envs/TS/lib/python3.5/site-packages/django/core/handlers/exception.py", line 41, in inner
    response = get_response(request)
  File "/root/Envs/TS/lib/python3.5/site-packages/django/core/handlers/base.py", line 187, in _get_response
    response = self.process_exception_by_middleware(e, request)
  File "/root/Envs/TS/lib/python3.5/site-packages/django/core/handlers/base.py", line 185, in _get_response
    response = wrapped_callback(request, *callback_args, **callback_kwargs)
  File "/opt/TS/StormwindCity/views.py", line 92, in TrustAsia_apply_Order_Authz
    result = TrustAsia_obj.Order_Authz(domain,order)
  File "/opt/TS/StormwindCity/FreeSSL.py", line 126, in Order_Authz
    verify_url = "order/authz/"+order+"?brand=trustasia"
TypeError: Can't convert 'NoneType' object to str implicitly
2018-08-11 18:00:46,570 - exception.py[line:135] - ERROR: Internal Server Error: /stormwindcity/api/freessl/order_detail/
Traceback (most recent call last):
  File "/root/Envs/TS/lib/python3.5/site-packages/django/core/handlers/exception.py", line 41, in inner
    response = get_response(request)
  File "/root/Envs/TS/lib/python3.5/site-packages/django/core/handlers/base.py", line 187, in _get_response
    response = self.process_exception_by_middleware(e, request)
  File "/root/Envs/TS/lib/python3.5/site-packages/django/core/handlers/base.py", line 185, in _get_response
    response = wrapped_callback(request, *callback_args, **callback_kwargs)
  File "/opt/TS/StormwindCity/views.py", line 213, in TrustAsia_order_detail
    order_id = json.loads(request.body.decode())['order_id']
  File "/usr/local/python3/lib/python3.5/json/__init__.py", line 319, in loads
    return _default_decoder.decode(s)
  File "/usr/local/python3/lib/python3.5/json/decoder.py", line 339, in decode
    obj, end = self.raw_decode(s, idx=_w(s, 0).end())
  File "/usr/local/python3/lib/python3.5/json/decoder.py", line 357, in raw_decode
    raise JSONDecodeError("Expecting value", s, err.value) from None
json.decoder.JSONDecodeError: Expecting value: line 1 column 1 (char 0)
2018-08-11 18:01:21,621 - exception.py[line:135] - ERROR: Internal Server Error: /stormwindcity/api/freessl/create_order/
Traceback (most recent call last):
  File "/root/Envs/TS/lib/python3.5/site-packages/django/core/handlers/exception.py", line 41, in inner
    response = get_response(request)
  File "/root/Envs/TS/lib/python3.5/site-packages/django/core/handlers/base.py", line 187, in _get_response
    response = self.process_exception_by_middleware(e, request)
  File "/root/Envs/TS/lib/python3.5/site-packages/django/core/handlers/base.py", line 185, in _get_response
    response = wrapped_callback(request, *callback_args, **callback_kwargs)
  File "/opt/TS/StormwindCity/views.py", line 57, in TrustAsia_apply_create_order
    domain = json.loads(request.body.decode())['domain']
  File "/usr/local/python3/lib/python3.5/json/__init__.py", line 319, in loads
    return _default_decoder.decode(s)
  File "/usr/local/python3/lib/python3.5/json/decoder.py", line 339, in decode
    obj, end = self.raw_decode(s, idx=_w(s, 0).end())
  File "/usr/local/python3/lib/python3.5/json/decoder.py", line 357, in raw_decode
    raise JSONDecodeError("Expecting value", s, err.value) from None
json.decoder.JSONDecodeError: Expecting value: line 1 column 1 (char 0)
2018-08-11 18:01:55,019 - exception.py[line:135] - ERROR: Internal Server Error: /stormwindcity/api/freessl/order_detail/
Traceback (most recent call last):
  File "/root/Envs/TS/lib/python3.5/site-packages/django/core/handlers/exception.py", line 41, in inner
    response = get_response(request)
  File "/root/Envs/TS/lib/python3.5/site-packages/django/core/handlers/base.py", line 187, in _get_response
    response = self.process_exception_by_middleware(e, request)
  File "/root/Envs/TS/lib/python3.5/site-packages/django/core/handlers/base.py", line 185, in _get_response
    response = wrapped_callback(request, *callback_args, **callback_kwargs)
  File "/opt/TS/StormwindCity/views.py", line 213, in TrustAsia_order_detail
    order_id = json.loads(request.body.decode())['order_id']
KeyError: 'order_id'
2018-08-11 18:02:15,984 - exception.py[line:135] - ERROR: Internal Server Error: /stormwindcity/api/freessl/order_detail/
Traceback (most recent call last):
  File "/root/Envs/TS/lib/python3.5/site-packages/django/core/handlers/exception.py", line 41, in inner
    response = get_response(request)
  File "/root/Envs/TS/lib/python3.5/site-packages/django/core/handlers/base.py", line 187, in _get_response
    response = self.process_exception_by_middleware(e, request)
  File "/root/Envs/TS/lib/python3.5/site-packages/django/core/handlers/base.py", line 185, in _get_response
    response = wrapped_callback(request, *callback_args, **callback_kwargs)
  File "/opt/TS/StormwindCity/views.py", line 213, in TrustAsia_order_detail
    order_id = json.loads(request.body.decode())['order_id']
  File "/usr/local/python3/lib/python3.5/json/__init__.py", line 319, in loads
    return _default_decoder.decode(s)
  File "/usr/local/python3/lib/python3.5/json/decoder.py", line 339, in decode
    obj, end = self.raw_decode(s, idx=_w(s, 0).end())
  File "/usr/local/python3/lib/python3.5/json/decoder.py", line 357, in raw_decode
    raise JSONDecodeError("Expecting value", s, err.value) from None
json.decoder.JSONDecodeError: Expecting value: line 1 column 1 (char 0)
2018-08-11 18:02:35,725 - exception.py[line:135] - ERROR: Internal Server Error: /stormwindcity/api/freessl/order_detail/
Traceback (most recent call last):
  File "/root/Envs/TS/lib/python3.5/site-packages/django/core/handlers/exception.py", line 41, in inner
    response = get_response(request)
  File "/root/Envs/TS/lib/python3.5/site-packages/django/core/handlers/base.py", line 187, in _get_response
    response = self.process_exception_by_middleware(e, request)
  File "/root/Envs/TS/lib/python3.5/site-packages/django/core/handlers/base.py", line 185, in _get_response
    response = wrapped_callback(request, *callback_args, **callback_kwargs)
  File "/opt/TS/StormwindCity/views.py", line 213, in TrustAsia_order_detail
    order_id = json.loads(request.body.decode())['order_id']
  File "/usr/local/python3/lib/python3.5/json/__init__.py", line 319, in loads
    return _default_decoder.decode(s)
  File "/usr/local/python3/lib/python3.5/json/decoder.py", line 339, in decode
    obj, end = self.raw_decode(s, idx=_w(s, 0).end())
  File "/usr/local/python3/lib/python3.5/json/decoder.py", line 357, in raw_decode
    raise JSONDecodeError("Expecting value", s, err.value) from None
json.decoder.JSONDecodeError: Expecting value: line 1 column 1 (char 0)
2018-08-13 09:22:45,073 - base.py[line:152] - WARNING: Not Found: /favicon.ico
2018-08-13 10:32:24,631 - base.py[line:152] - WARNING: Not Found: /stormwindcity/api/freessl/delete/
2018-08-13 10:32:52,644 - exception.py[line:135] - ERROR: Internal Server Error: /stormwindcity/api/freessl/order_delete/
Traceback (most recent call last):
  File "/root/Envs/TS/lib/python3.5/site-packages/django/core/handlers/exception.py", line 41, in inner
    response = get_response(request)
  File "/root/Envs/TS/lib/python3.5/site-packages/django/core/handlers/base.py", line 187, in _get_response
    response = self.process_exception_by_middleware(e, request)
  File "/root/Envs/TS/lib/python3.5/site-packages/django/core/handlers/base.py", line 185, in _get_response
    response = wrapped_callback(request, *callback_args, **callback_kwargs)
  File "/opt/TS/StormwindCity/views.py", line 232, in TrustAsia_order_delete
    result = TrustAsia_obj.Order_delete(order_id,status)
  File "/opt/TS/StormwindCity/FreeSSL.py", line 86, in Order_delete
    response = self.requests.post("orders/delete/"+order_id,headers=self.headers)
TypeError: Can't convert 'NoneType' object to str implicitly
2018-08-13 16:26:32,405 - base.py[line:152] - WARNING: Not Found: /favicon.ico
2018-08-13 17:12:43,490 - base.py[line:152] - WARNING: Not Found: /favicon.ico
2018-08-13 17:13:30,229 - base.py[line:152] - WARNING: Not Found: /favicon.ico
2018-08-13 17:41:40,592 - exception.py[line:135] - ERROR: Internal Server Error: /stormwindcity/api/freessl/cert_select/
Traceback (most recent call last):
  File "/root/Envs/TS/lib/python3.5/site-packages/django/core/handlers/exception.py", line 41, in inner
    response = get_response(request)
  File "/root/Envs/TS/lib/python3.5/site-packages/django/core/handlers/base.py", line 198, in _get_response
    "returned None instead." % (callback.__module__, view_name)
ValueError: The view StormwindCity.views.TrustAsia_cert_select didn't return an HttpResponse object. It returned None instead.
2018-08-13 17:42:54,655 - exception.py[line:135] - ERROR: Internal Server Error: /stormwindcity/api/freessl/cert_select/
Traceback (most recent call last):
  File "/root/Envs/TS/lib/python3.5/site-packages/django/core/handlers/exception.py", line 41, in inner
    response = get_response(request)
  File "/root/Envs/TS/lib/python3.5/site-packages/django/core/handlers/base.py", line 187, in _get_response
    response = self.process_exception_by_middleware(e, request)
  File "/root/Envs/TS/lib/python3.5/site-packages/django/core/handlers/base.py", line 185, in _get_response
    response = wrapped_callback(request, *callback_args, **callback_kwargs)
  File "/opt/TS/StormwindCity/views.py", line 254, in TrustAsia_cert_select
    order_id = json.loads(request.body.decode())['order_id']
  File "/usr/local/python3/lib/python3.5/json/__init__.py", line 319, in loads
    return _default_decoder.decode(s)
  File "/usr/local/python3/lib/python3.5/json/decoder.py", line 339, in decode
    obj, end = self.raw_decode(s, idx=_w(s, 0).end())
  File "/usr/local/python3/lib/python3.5/json/decoder.py", line 357, in raw_decode
    raise JSONDecodeError("Expecting value", s, err.value) from None
json.decoder.JSONDecodeError: Expecting value: line 1 column 1 (char 0)
2018-08-13 17:44:22,552 - exception.py[line:135] - ERROR: Internal Server Error: /stormwindcity/api/freessl/cert_select/
Traceback (most recent call last):
  File "/root/Envs/TS/lib/python3.5/site-packages/django/core/handlers/exception.py", line 41, in inner
    response = get_response(request)
  File "/root/Envs/TS/lib/python3.5/site-packages/django/core/handlers/base.py", line 187, in _get_response
    response = self.process_exception_by_middleware(e, request)
  File "/root/Envs/TS/lib/python3.5/site-packages/django/core/handlers/base.py", line 185, in _get_response
    response = wrapped_callback(request, *callback_args, **callback_kwargs)
  File "/opt/TS/StormwindCity/views.py", line 255, in TrustAsia_cert_select
    order_id = json.loads(request.body.decode())['order_id']
  File "/usr/local/python3/lib/python3.5/json/__init__.py", line 319, in loads
    return _default_decoder.decode(s)
  File "/usr/local/python3/lib/python3.5/json/decoder.py", line 339, in decode
    obj, end = self.raw_decode(s, idx=_w(s, 0).end())
  File "/usr/local/python3/lib/python3.5/json/decoder.py", line 357, in raw_decode
    raise JSONDecodeError("Expecting value", s, err.value) from None
json.decoder.JSONDecodeError: Expecting value: line 1 column 1 (char 0)
2018-08-13 17:44:32,250 - exception.py[line:135] - ERROR: Internal Server Error: /stormwindcity/api/freessl/cert_select/
Traceback (most recent call last):
  File "/root/Envs/TS/lib/python3.5/site-packages/django/core/handlers/exception.py", line 41, in inner
    response = get_response(request)
  File "/root/Envs/TS/lib/python3.5/site-packages/django/core/handlers/base.py", line 187, in _get_response
    response = self.process_exception_by_middleware(e, request)
  File "/root/Envs/TS/lib/python3.5/site-packages/django/core/handlers/base.py", line 185, in _get_response
    response = wrapped_callback(request, *callback_args, **callback_kwargs)
  File "/opt/TS/StormwindCity/views.py", line 255, in TrustAsia_cert_select
    order_id = json.loads(request.body.decode())['order_id']
  File "/usr/local/python3/lib/python3.5/json/__init__.py", line 319, in loads
    return _default_decoder.decode(s)
  File "/usr/local/python3/lib/python3.5/json/decoder.py", line 339, in decode
    obj, end = self.raw_decode(s, idx=_w(s, 0).end())
  File "/usr/local/python3/lib/python3.5/json/decoder.py", line 357, in raw_decode
    raise JSONDecodeError("Expecting value", s, err.value) from None
json.decoder.JSONDecodeError: Expecting value: line 1 column 1 (char 0)
2018-08-13 17:46:21,372 - exception.py[line:135] - ERROR: Internal Server Error: /stormwindcity/api/freessl/cert_select/
Traceback (most recent call last):
  File "/root/Envs/TS/lib/python3.5/site-packages/django/core/handlers/exception.py", line 41, in inner
    response = get_response(request)
  File "/root/Envs/TS/lib/python3.5/site-packages/django/core/handlers/base.py", line 187, in _get_response
    response = self.process_exception_by_middleware(e, request)
  File "/root/Envs/TS/lib/python3.5/site-packages/django/core/handlers/base.py", line 185, in _get_response
    response = wrapped_callback(request, *callback_args, **callback_kwargs)
  File "/opt/TS/StormwindCity/views.py", line 255, in TrustAsia_cert_select
    order_id = json.loads(request.body.decode())['order_id']
  File "/usr/local/python3/lib/python3.5/json/__init__.py", line 319, in loads
    return _default_decoder.decode(s)
  File "/usr/local/python3/lib/python3.5/json/decoder.py", line 339, in decode
    obj, end = self.raw_decode(s, idx=_w(s, 0).end())
  File "/usr/local/python3/lib/python3.5/json/decoder.py", line 357, in raw_decode
    raise JSONDecodeError("Expecting value", s, err.value) from None
json.decoder.JSONDecodeError: Expecting value: line 1 column 1 (char 0)
2018-08-13 17:46:32,836 - exception.py[line:135] - ERROR: Internal Server Error: /stormwindcity/api/freessl/cert_select/
Traceback (most recent call last):
  File "/root/Envs/TS/lib/python3.5/site-packages/django/core/handlers/exception.py", line 41, in inner
    response = get_response(request)
  File "/root/Envs/TS/lib/python3.5/site-packages/django/core/handlers/base.py", line 187, in _get_response
    response = self.process_exception_by_middleware(e, request)
  File "/root/Envs/TS/lib/python3.5/site-packages/django/core/handlers/base.py", line 185, in _get_response
    response = wrapped_callback(request, *callback_args, **callback_kwargs)
  File "/opt/TS/StormwindCity/views.py", line 255, in TrustAsia_cert_select
    order_id = json.loads(request.body.decode())['order_id']
  File "/usr/local/python3/lib/python3.5/json/__init__.py", line 319, in loads
    return _default_decoder.decode(s)
  File "/usr/local/python3/lib/python3.5/json/decoder.py", line 339, in decode
    obj, end = self.raw_decode(s, idx=_w(s, 0).end())
  File "/usr/local/python3/lib/python3.5/json/decoder.py", line 357, in raw_decode
    raise JSONDecodeError("Expecting value", s, err.value) from None
json.decoder.JSONDecodeError: Expecting value: line 1 column 1 (char 0)
2018-08-13 17:47:00,982 - exception.py[line:135] - ERROR: Internal Server Error: /stormwindcity/api/freessl/cert_select/
Traceback (most recent call last):
  File "/root/Envs/TS/lib/python3.5/site-packages/django/core/handlers/exception.py", line 41, in inner
    response = get_response(request)
  File "/root/Envs/TS/lib/python3.5/site-packages/django/core/handlers/base.py", line 187, in _get_response
    response = self.process_exception_by_middleware(e, request)
  File "/root/Envs/TS/lib/python3.5/site-packages/django/core/handlers/base.py", line 185, in _get_response
    response = wrapped_callback(request, *callback_args, **callback_kwargs)
  File "/opt/TS/StormwindCity/views.py", line 255, in TrustAsia_cert_select
    order_id = json.loads(request.body.decode())['order_id']
  File "/usr/local/python3/lib/python3.5/json/__init__.py", line 319, in loads
    return _default_decoder.decode(s)
  File "/usr/local/python3/lib/python3.5/json/decoder.py", line 339, in decode
    obj, end = self.raw_decode(s, idx=_w(s, 0).end())
  File "/usr/local/python3/lib/python3.5/json/decoder.py", line 357, in raw_decode
    raise JSONDecodeError("Expecting value", s, err.value) from None
json.decoder.JSONDecodeError: Expecting value: line 1 column 1 (char 0)
2018-08-14 17:04:33,193 - base.py[line:152] - WARNING: Not Found: /spiderkingdom/api/domains/18/
2018-08-14 17:05:55,058 - base.py[line:152] - WARNING: Not Found: /spiderkingdom/api/domains/18/
2018-08-15 10:12:08,259 - exception.py[line:135] - ERROR: Internal Server Error: /spiderkingdom/api/domains/12/
Traceback (most recent call last):
  File "/root/Envs/TS/lib/python3.5/site-packages/django/core/handlers/exception.py", line 41, in inner
    response = get_response(request)
  File "/root/Envs/TS/lib/python3.5/site-packages/django/core/handlers/base.py", line 187, in _get_response
    response = self.process_exception_by_middleware(e, request)
  File "/root/Envs/TS/lib/python3.5/site-packages/django/core/handlers/base.py", line 185, in _get_response
    response = wrapped_callback(request, *callback_args, **callback_kwargs)
  File "/root/Envs/TS/lib/python3.5/site-packages/django/views/decorators/csrf.py", line 58, in wrapped_view
    return view_func(*args, **kwargs)
  File "/root/Envs/TS/lib/python3.5/site-packages/rest_framework/viewsets.py", line 103, in view
    return self.dispatch(request, *args, **kwargs)
  File "/root/Envs/TS/lib/python3.5/site-packages/rest_framework/views.py", line 483, in dispatch
    response = self.handle_exception(exc)
  File "/root/Envs/TS/lib/python3.5/site-packages/rest_framework/views.py", line 443, in handle_exception
    self.raise_uncaught_exception(exc)
  File "/root/Envs/TS/lib/python3.5/site-packages/rest_framework/views.py", line 480, in dispatch
    response = handler(request, *args, **kwargs)
  File "/root/Envs/TS/lib/python3.5/site-packages/rest_framework/mixins.py", line 58, in retrieve
    return Response(serializer.data)
  File "/root/Envs/TS/lib/python3.5/site-packages/rest_framework/serializers.py", line 560, in data
    ret = super(Serializer, self).data
  File "/root/Envs/TS/lib/python3.5/site-packages/rest_framework/serializers.py", line 262, in data
    self._data = self.to_representation(self.instance)
  File "/root/Envs/TS/lib/python3.5/site-packages/rest_framework/serializers.py", line 510, in to_representation
    fields = self._readable_fields
  File "/root/Envs/TS/lib/python3.5/site-packages/django/utils/functional.py", line 35, in __get__
    res = instance.__dict__[self.name] = self.func(instance)
  File "/root/Envs/TS/lib/python3.5/site-packages/rest_framework/serializers.py", line 376, in _readable_fields
    field for field in self.fields.values()
  File "/root/Envs/TS/lib/python3.5/site-packages/rest_framework/serializers.py", line 363, in fields
    for key, value in self.get_fields().items():
  File "/root/Envs/TS/lib/python3.5/site-packages/rest_framework/serializers.py", line 1045, in get_fields
    source, info, model, depth
  File "/root/Envs/TS/lib/python3.5/site-packages/rest_framework/serializers.py", line 1190, in build_field
    return self.build_unknown_field(field_name, model_class)
  File "/root/Envs/TS/lib/python3.5/site-packages/rest_framework/serializers.py", line 1302, in build_unknown_field
    (field_name, model_class.__name__)
django.core.exceptions.ImproperlyConfigured: Field name `not_check` is not valid for model `Domain`.
2018-08-15 10:12:13,884 - exception.py[line:135] - ERROR: Internal Server Error: /spiderkingdom/api/domains/16/
Traceback (most recent call last):
  File "/root/Envs/TS/lib/python3.5/site-packages/django/core/handlers/exception.py", line 41, in inner
    response = get_response(request)
  File "/root/Envs/TS/lib/python3.5/site-packages/django/core/handlers/base.py", line 187, in _get_response
    response = self.process_exception_by_middleware(e, request)
  File "/root/Envs/TS/lib/python3.5/site-packages/django/core/handlers/base.py", line 185, in _get_response
    response = wrapped_callback(request, *callback_args, **callback_kwargs)
  File "/root/Envs/TS/lib/python3.5/site-packages/django/views/decorators/csrf.py", line 58, in wrapped_view
    return view_func(*args, **kwargs)
  File "/root/Envs/TS/lib/python3.5/site-packages/rest_framework/viewsets.py", line 103, in view
    return self.dispatch(request, *args, **kwargs)
  File "/root/Envs/TS/lib/python3.5/site-packages/rest_framework/views.py", line 483, in dispatch
    response = self.handle_exception(exc)
  File "/root/Envs/TS/lib/python3.5/site-packages/rest_framework/views.py", line 443, in handle_exception
    self.raise_uncaught_exception(exc)
  File "/root/Envs/TS/lib/python3.5/site-packages/rest_framework/views.py", line 480, in dispatch
    response = handler(request, *args, **kwargs)
  File "/root/Envs/TS/lib/python3.5/site-packages/rest_framework/mixins.py", line 58, in retrieve
    return Response(serializer.data)
  File "/root/Envs/TS/lib/python3.5/site-packages/rest_framework/serializers.py", line 560, in data
    ret = super(Serializer, self).data
  File "/root/Envs/TS/lib/python3.5/site-packages/rest_framework/serializers.py", line 262, in data
    self._data = self.to_representation(self.instance)
  File "/root/Envs/TS/lib/python3.5/site-packages/rest_framework/serializers.py", line 510, in to_representation
    fields = self._readable_fields
  File "/root/Envs/TS/lib/python3.5/site-packages/django/utils/functional.py", line 35, in __get__
    res = instance.__dict__[self.name] = self.func(instance)
  File "/root/Envs/TS/lib/python3.5/site-packages/rest_framework/serializers.py", line 376, in _readable_fields
    field for field in self.fields.values()
  File "/root/Envs/TS/lib/python3.5/site-packages/rest_framework/serializers.py", line 363, in fields
    for key, value in self.get_fields().items():
  File "/root/Envs/TS/lib/python3.5/site-packages/rest_framework/serializers.py", line 1045, in get_fields
    source, info, model, depth
  File "/root/Envs/TS/lib/python3.5/site-packages/rest_framework/serializers.py", line 1190, in build_field
    return self.build_unknown_field(field_name, model_class)
  File "/root/Envs/TS/lib/python3.5/site-packages/rest_framework/serializers.py", line 1302, in build_unknown_field
    (field_name, model_class.__name__)
django.core.exceptions.ImproperlyConfigured: Field name `not_check` is not valid for model `Domain`.
2018-08-15 10:12:40,290 - exception.py[line:135] - ERROR: Internal Server Error: /spiderkingdom/api/domains/46/
Traceback (most recent call last):
  File "/root/Envs/TS/lib/python3.5/site-packages/django/core/handlers/exception.py", line 41, in inner
    response = get_response(request)
  File "/root/Envs/TS/lib/python3.5/site-packages/django/core/handlers/base.py", line 187, in _get_response
    response = self.process_exception_by_middleware(e, request)
  File "/root/Envs/TS/lib/python3.5/site-packages/django/core/handlers/base.py", line 185, in _get_response
    response = wrapped_callback(request, *callback_args, **callback_kwargs)
  File "/root/Envs/TS/lib/python3.5/site-packages/django/views/decorators/csrf.py", line 58, in wrapped_view
    return view_func(*args, **kwargs)
  File "/root/Envs/TS/lib/python3.5/site-packages/rest_framework/viewsets.py", line 103, in view
    return self.dispatch(request, *args, **kwargs)
  File "/root/Envs/TS/lib/python3.5/site-packages/rest_framework/views.py", line 483, in dispatch
    response = self.handle_exception(exc)
  File "/root/Envs/TS/lib/python3.5/site-packages/rest_framework/views.py", line 443, in handle_exception
    self.raise_uncaught_exception(exc)
  File "/root/Envs/TS/lib/python3.5/site-packages/rest_framework/views.py", line 480, in dispatch
    response = handler(request, *args, **kwargs)
  File "/root/Envs/TS/lib/python3.5/site-packages/rest_framework/mixins.py", line 58, in retrieve
    return Response(serializer.data)
  File "/root/Envs/TS/lib/python3.5/site-packages/rest_framework/serializers.py", line 560, in data
    ret = super(Serializer, self).data
  File "/root/Envs/TS/lib/python3.5/site-packages/rest_framework/serializers.py", line 262, in data
    self._data = self.to_representation(self.instance)
  File "/root/Envs/TS/lib/python3.5/site-packages/rest_framework/serializers.py", line 510, in to_representation
    fields = self._readable_fields
  File "/root/Envs/TS/lib/python3.5/site-packages/django/utils/functional.py", line 35, in __get__
    res = instance.__dict__[self.name] = self.func(instance)
  File "/root/Envs/TS/lib/python3.5/site-packages/rest_framework/serializers.py", line 376, in _readable_fields
    field for field in self.fields.values()
  File "/root/Envs/TS/lib/python3.5/site-packages/rest_framework/serializers.py", line 363, in fields
    for key, value in self.get_fields().items():
  File "/root/Envs/TS/lib/python3.5/site-packages/rest_framework/serializers.py", line 1045, in get_fields
    source, info, model, depth
  File "/root/Envs/TS/lib/python3.5/site-packages/rest_framework/serializers.py", line 1190, in build_field
    return self.build_unknown_field(field_name, model_class)
  File "/root/Envs/TS/lib/python3.5/site-packages/rest_framework/serializers.py", line 1302, in build_unknown_field
    (field_name, model_class.__name__)
django.core.exceptions.ImproperlyConfigured: Field name `not_check` is not valid for model `Domain`.
2018-08-15 10:14:54,367 - exception.py[line:135] - ERROR: Internal Server Error: /spiderkingdom/api/domains/
Traceback (most recent call last):
  File "/root/Envs/TS/lib/python3.5/site-packages/django/core/handlers/exception.py", line 41, in inner
    response = get_response(request)
  File "/root/Envs/TS/lib/python3.5/site-packages/django/core/handlers/base.py", line 187, in _get_response
    response = self.process_exception_by_middleware(e, request)
  File "/root/Envs/TS/lib/python3.5/site-packages/django/core/handlers/base.py", line 185, in _get_response
    response = wrapped_callback(request, *callback_args, **callback_kwargs)
  File "/root/Envs/TS/lib/python3.5/site-packages/django/views/decorators/csrf.py", line 58, in wrapped_view
    return view_func(*args, **kwargs)
  File "/root/Envs/TS/lib/python3.5/site-packages/rest_framework/viewsets.py", line 103, in view
    return self.dispatch(request, *args, **kwargs)
  File "/root/Envs/TS/lib/python3.5/site-packages/rest_framework/views.py", line 483, in dispatch
    response = self.handle_exception(exc)
  File "/root/Envs/TS/lib/python3.5/site-packages/rest_framework/views.py", line 443, in handle_exception
    self.raise_uncaught_exception(exc)
  File "/root/Envs/TS/lib/python3.5/site-packages/rest_framework/views.py", line 480, in dispatch
    response = handler(request, *args, **kwargs)
  File "/root/Envs/TS/lib/python3.5/site-packages/rest_framework/mixins.py", line 45, in list
    return self.get_paginated_response(serializer.data)
  File "/root/Envs/TS/lib/python3.5/site-packages/rest_framework/serializers.py", line 765, in data
    ret = super(ListSerializer, self).data
  File "/root/Envs/TS/lib/python3.5/site-packages/rest_framework/serializers.py", line 262, in data
    self._data = self.to_representation(self.instance)
  File "/root/Envs/TS/lib/python3.5/site-packages/rest_framework/serializers.py", line 683, in to_representation
    self.child.to_representation(item) for item in iterable
  File "/root/Envs/TS/lib/python3.5/site-packages/rest_framework/serializers.py", line 683, in <listcomp>
    self.child.to_representation(item) for item in iterable
  File "/root/Envs/TS/lib/python3.5/site-packages/rest_framework/serializers.py", line 510, in to_representation
    fields = self._readable_fields
  File "/root/Envs/TS/lib/python3.5/site-packages/django/utils/functional.py", line 35, in __get__
    res = instance.__dict__[self.name] = self.func(instance)
  File "/root/Envs/TS/lib/python3.5/site-packages/rest_framework/serializers.py", line 376, in _readable_fields
    field for field in self.fields.values()
  File "/root/Envs/TS/lib/python3.5/site-packages/rest_framework/serializers.py", line 363, in fields
    for key, value in self.get_fields().items():
  File "/root/Envs/TS/lib/python3.5/site-packages/rest_framework/serializers.py", line 1045, in get_fields
    source, info, model, depth
  File "/root/Envs/TS/lib/python3.5/site-packages/rest_framework/serializers.py", line 1190, in build_field
    return self.build_unknown_field(field_name, model_class)
  File "/root/Envs/TS/lib/python3.5/site-packages/rest_framework/serializers.py", line 1302, in build_unknown_field
    (field_name, model_class.__name__)
django.core.exceptions.ImproperlyConfigured: Field name `not_check` is not valid for model `Domain`.
2018-08-15 10:15:59,799 - exception.py[line:135] - ERROR: Internal Server Error: /spiderkingdom/api/domains/
Traceback (most recent call last):
  File "/root/Envs/TS/lib/python3.5/site-packages/django/core/handlers/exception.py", line 41, in inner
    response = get_response(request)
  File "/root/Envs/TS/lib/python3.5/site-packages/django/core/handlers/base.py", line 187, in _get_response
    response = self.process_exception_by_middleware(e, request)
  File "/root/Envs/TS/lib/python3.5/site-packages/django/core/handlers/base.py", line 185, in _get_response
    response = wrapped_callback(request, *callback_args, **callback_kwargs)
  File "/root/Envs/TS/lib/python3.5/site-packages/django/views/decorators/csrf.py", line 58, in wrapped_view
    return view_func(*args, **kwargs)
  File "/root/Envs/TS/lib/python3.5/site-packages/rest_framework/viewsets.py", line 103, in view
    return self.dispatch(request, *args, **kwargs)
  File "/root/Envs/TS/lib/python3.5/site-packages/rest_framework/views.py", line 483, in dispatch
    response = self.handle_exception(exc)
  File "/root/Envs/TS/lib/python3.5/site-packages/rest_framework/views.py", line 443, in handle_exception
    self.raise_uncaught_exception(exc)
  File "/root/Envs/TS/lib/python3.5/site-packages/rest_framework/views.py", line 480, in dispatch
    response = handler(request, *args, **kwargs)
  File "/root/Envs/TS/lib/python3.5/site-packages/rest_framework/mixins.py", line 45, in list
    return self.get_paginated_response(serializer.data)
  File "/root/Envs/TS/lib/python3.5/site-packages/rest_framework/serializers.py", line 765, in data
    ret = super(ListSerializer, self).data
  File "/root/Envs/TS/lib/python3.5/site-packages/rest_framework/serializers.py", line 262, in data
    self._data = self.to_representation(self.instance)
  File "/root/Envs/TS/lib/python3.5/site-packages/rest_framework/serializers.py", line 683, in to_representation
    self.child.to_representation(item) for item in iterable
  File "/root/Envs/TS/lib/python3.5/site-packages/rest_framework/serializers.py", line 683, in <listcomp>
    self.child.to_representation(item) for item in iterable
  File "/root/Envs/TS/lib/python3.5/site-packages/rest_framework/serializers.py", line 510, in to_representation
    fields = self._readable_fields
  File "/root/Envs/TS/lib/python3.5/site-packages/django/utils/functional.py", line 35, in __get__
    res = instance.__dict__[self.name] = self.func(instance)
  File "/root/Envs/TS/lib/python3.5/site-packages/rest_framework/serializers.py", line 376, in _readable_fields
    field for field in self.fields.values()
  File "/root/Envs/TS/lib/python3.5/site-packages/rest_framework/serializers.py", line 363, in fields
    for key, value in self.get_fields().items():
  File "/root/Envs/TS/lib/python3.5/site-packages/rest_framework/serializers.py", line 1045, in get_fields
    source, info, model, depth
  File "/root/Envs/TS/lib/python3.5/site-packages/rest_framework/serializers.py", line 1190, in build_field
    return self.build_unknown_field(field_name, model_class)
  File "/root/Envs/TS/lib/python3.5/site-packages/rest_framework/serializers.py", line 1302, in build_unknown_field
    (field_name, model_class.__name__)
django.core.exceptions.ImproperlyConfigured: Field name `not_check` is not valid for model `Domain`.
2018-08-15 10:16:53,101 - exception.py[line:135] - ERROR: Internal Server Error: /spiderkingdom/api/domains/
Traceback (most recent call last):
  File "/root/Envs/TS/lib/python3.5/site-packages/django/core/handlers/exception.py", line 41, in inner
    response = get_response(request)
  File "/root/Envs/TS/lib/python3.5/site-packages/django/core/handlers/base.py", line 187, in _get_response
    response = self.process_exception_by_middleware(e, request)
  File "/root/Envs/TS/lib/python3.5/site-packages/django/core/handlers/base.py", line 185, in _get_response
    response = wrapped_callback(request, *callback_args, **callback_kwargs)
  File "/root/Envs/TS/lib/python3.5/site-packages/django/views/decorators/csrf.py", line 58, in wrapped_view
    return view_func(*args, **kwargs)
  File "/root/Envs/TS/lib/python3.5/site-packages/rest_framework/viewsets.py", line 103, in view
    return self.dispatch(request, *args, **kwargs)
  File "/root/Envs/TS/lib/python3.5/site-packages/rest_framework/views.py", line 483, in dispatch
    response = self.handle_exception(exc)
  File "/root/Envs/TS/lib/python3.5/site-packages/rest_framework/views.py", line 443, in handle_exception
    self.raise_uncaught_exception(exc)
  File "/root/Envs/TS/lib/python3.5/site-packages/rest_framework/views.py", line 480, in dispatch
    response = handler(request, *args, **kwargs)
  File "/root/Envs/TS/lib/python3.5/site-packages/rest_framework/mixins.py", line 45, in list
    return self.get_paginated_response(serializer.data)
  File "/root/Envs/TS/lib/python3.5/site-packages/rest_framework/serializers.py", line 765, in data
    ret = super(ListSerializer, self).data
  File "/root/Envs/TS/lib/python3.5/site-packages/rest_framework/serializers.py", line 262, in data
    self._data = self.to_representation(self.instance)
  File "/root/Envs/TS/lib/python3.5/site-packages/rest_framework/serializers.py", line 683, in to_representation
    self.child.to_representation(item) for item in iterable
  File "/root/Envs/TS/lib/python3.5/site-packages/rest_framework/serializers.py", line 683, in <listcomp>
    self.child.to_representation(item) for item in iterable
  File "/root/Envs/TS/lib/python3.5/site-packages/rest_framework/serializers.py", line 510, in to_representation
    fields = self._readable_fields
  File "/root/Envs/TS/lib/python3.5/site-packages/django/utils/functional.py", line 35, in __get__
    res = instance.__dict__[self.name] = self.func(instance)
  File "/root/Envs/TS/lib/python3.5/site-packages/rest_framework/serializers.py", line 376, in _readable_fields
    field for field in self.fields.values()
  File "/root/Envs/TS/lib/python3.5/site-packages/rest_framework/serializers.py", line 363, in fields
    for key, value in self.get_fields().items():
  File "/root/Envs/TS/lib/python3.5/site-packages/rest_framework/serializers.py", line 1045, in get_fields
    source, info, model, depth
  File "/root/Envs/TS/lib/python3.5/site-packages/rest_framework/serializers.py", line 1190, in build_field
    return self.build_unknown_field(field_name, model_class)
  File "/root/Envs/TS/lib/python3.5/site-packages/rest_framework/serializers.py", line 1302, in build_unknown_field
    (field_name, model_class.__name__)
django.core.exceptions.ImproperlyConfigured: Field name `not_check` is not valid for model `Domain`.
2018-08-15 10:30:59,517 - exception.py[line:135] - ERROR: Internal Server Error: /spiderkingdom/api/domains/46/
Traceback (most recent call last):
  File "/root/Envs/TS/lib/python3.5/site-packages/django/core/handlers/exception.py", line 41, in inner
    response = get_response(request)
  File "/root/Envs/TS/lib/python3.5/site-packages/django/core/handlers/base.py", line 187, in _get_response
    response = self.process_exception_by_middleware(e, request)
  File "/root/Envs/TS/lib/python3.5/site-packages/django/core/handlers/base.py", line 185, in _get_response
    response = wrapped_callback(request, *callback_args, **callback_kwargs)
  File "/root/Envs/TS/lib/python3.5/site-packages/django/views/decorators/csrf.py", line 58, in wrapped_view
    return view_func(*args, **kwargs)
  File "/root/Envs/TS/lib/python3.5/site-packages/rest_framework/viewsets.py", line 103, in view
    return self.dispatch(request, *args, **kwargs)
  File "/root/Envs/TS/lib/python3.5/site-packages/rest_framework/views.py", line 483, in dispatch
    response = self.handle_exception(exc)
  File "/root/Envs/TS/lib/python3.5/site-packages/rest_framework/views.py", line 443, in handle_exception
    self.raise_uncaught_exception(exc)
  File "/root/Envs/TS/lib/python3.5/site-packages/rest_framework/views.py", line 480, in dispatch
    response = handler(request, *args, **kwargs)
  File "/root/Envs/TS/lib/python3.5/site-packages/rest_framework/mixins.py", line 58, in retrieve
    return Response(serializer.data)
  File "/root/Envs/TS/lib/python3.5/site-packages/rest_framework/serializers.py", line 560, in data
    ret = super(Serializer, self).data
  File "/root/Envs/TS/lib/python3.5/site-packages/rest_framework/serializers.py", line 262, in data
    self._data = self.to_representation(self.instance)
  File "/root/Envs/TS/lib/python3.5/site-packages/rest_framework/serializers.py", line 510, in to_representation
    fields = self._readable_fields
  File "/root/Envs/TS/lib/python3.5/site-packages/django/utils/functional.py", line 35, in __get__
    res = instance.__dict__[self.name] = self.func(instance)
  File "/root/Envs/TS/lib/python3.5/site-packages/rest_framework/serializers.py", line 376, in _readable_fields
    field for field in self.fields.values()
  File "/root/Envs/TS/lib/python3.5/site-packages/rest_framework/serializers.py", line 364, in fields
    self._fields[key] = value
  File "/root/Envs/TS/lib/python3.5/site-packages/rest_framework/utils/serializer_helpers.py", line 148, in __setitem__
    field.bind(field_name=key, parent=self.serializer)
  File "/root/Envs/TS/lib/python3.5/site-packages/rest_framework/fields.py", line 385, in bind
    self.source_attrs = self.source.split('.')
AttributeError: 'int' object has no attribute 'split'
2018-08-15 10:31:18,016 - exception.py[line:135] - ERROR: Internal Server Error: /spiderkingdom/api/domains/
Traceback (most recent call last):
  File "/root/Envs/TS/lib/python3.5/site-packages/django/core/handlers/exception.py", line 41, in inner
    response = get_response(request)
  File "/root/Envs/TS/lib/python3.5/site-packages/django/core/handlers/base.py", line 187, in _get_response
    response = self.process_exception_by_middleware(e, request)
  File "/root/Envs/TS/lib/python3.5/site-packages/django/core/handlers/base.py", line 185, in _get_response
    response = wrapped_callback(request, *callback_args, **callback_kwargs)
  File "/root/Envs/TS/lib/python3.5/site-packages/django/views/decorators/csrf.py", line 58, in wrapped_view
    return view_func(*args, **kwargs)
  File "/root/Envs/TS/lib/python3.5/site-packages/rest_framework/viewsets.py", line 103, in view
    return self.dispatch(request, *args, **kwargs)
  File "/root/Envs/TS/lib/python3.5/site-packages/rest_framework/views.py", line 483, in dispatch
    response = self.handle_exception(exc)
  File "/root/Envs/TS/lib/python3.5/site-packages/rest_framework/views.py", line 443, in handle_exception
    self.raise_uncaught_exception(exc)
  File "/root/Envs/TS/lib/python3.5/site-packages/rest_framework/views.py", line 480, in dispatch
    response = handler(request, *args, **kwargs)
  File "/root/Envs/TS/lib/python3.5/site-packages/rest_framework/mixins.py", line 45, in list
    return self.get_paginated_response(serializer.data)
  File "/root/Envs/TS/lib/python3.5/site-packages/rest_framework/serializers.py", line 765, in data
    ret = super(ListSerializer, self).data
  File "/root/Envs/TS/lib/python3.5/site-packages/rest_framework/serializers.py", line 262, in data
    self._data = self.to_representation(self.instance)
  File "/root/Envs/TS/lib/python3.5/site-packages/rest_framework/serializers.py", line 683, in to_representation
    self.child.to_representation(item) for item in iterable
  File "/root/Envs/TS/lib/python3.5/site-packages/rest_framework/serializers.py", line 683, in <listcomp>
    self.child.to_representation(item) for item in iterable
  File "/root/Envs/TS/lib/python3.5/site-packages/rest_framework/serializers.py", line 510, in to_representation
    fields = self._readable_fields
  File "/root/Envs/TS/lib/python3.5/site-packages/django/utils/functional.py", line 35, in __get__
    res = instance.__dict__[self.name] = self.func(instance)
  File "/root/Envs/TS/lib/python3.5/site-packages/rest_framework/serializers.py", line 376, in _readable_fields
    field for field in self.fields.values()
  File "/root/Envs/TS/lib/python3.5/site-packages/rest_framework/serializers.py", line 364, in fields
    self._fields[key] = value
  File "/root/Envs/TS/lib/python3.5/site-packages/rest_framework/utils/serializer_helpers.py", line 148, in __setitem__
    field.bind(field_name=key, parent=self.serializer)
  File "/root/Envs/TS/lib/python3.5/site-packages/rest_framework/fields.py", line 385, in bind
    self.source_attrs = self.source.split('.')
AttributeError: 'int' object has no attribute 'split'
2018-08-15 10:31:19,694 - exception.py[line:135] - ERROR: Internal Server Error: /spiderkingdom/api/domains/
Traceback (most recent call last):
  File "/root/Envs/TS/lib/python3.5/site-packages/django/core/handlers/exception.py", line 41, in inner
    response = get_response(request)
  File "/root/Envs/TS/lib/python3.5/site-packages/django/core/handlers/base.py", line 187, in _get_response
    response = self.process_exception_by_middleware(e, request)
  File "/root/Envs/TS/lib/python3.5/site-packages/django/core/handlers/base.py", line 185, in _get_response
    response = wrapped_callback(request, *callback_args, **callback_kwargs)
  File "/root/Envs/TS/lib/python3.5/site-packages/django/views/decorators/csrf.py", line 58, in wrapped_view
    return view_func(*args, **kwargs)
  File "/root/Envs/TS/lib/python3.5/site-packages/rest_framework/viewsets.py", line 103, in view
    return self.dispatch(request, *args, **kwargs)
  File "/root/Envs/TS/lib/python3.5/site-packages/rest_framework/views.py", line 483, in dispatch
    response = self.handle_exception(exc)
  File "/root/Envs/TS/lib/python3.5/site-packages/rest_framework/views.py", line 443, in handle_exception
    self.raise_uncaught_exception(exc)
  File "/root/Envs/TS/lib/python3.5/site-packages/rest_framework/views.py", line 480, in dispatch
    response = handler(request, *args, **kwargs)
  File "/root/Envs/TS/lib/python3.5/site-packages/rest_framework/mixins.py", line 45, in list
    return self.get_paginated_response(serializer.data)
  File "/root/Envs/TS/lib/python3.5/site-packages/rest_framework/serializers.py", line 765, in data
    ret = super(ListSerializer, self).data
  File "/root/Envs/TS/lib/python3.5/site-packages/rest_framework/serializers.py", line 262, in data
    self._data = self.to_representation(self.instance)
  File "/root/Envs/TS/lib/python3.5/site-packages/rest_framework/serializers.py", line 683, in to_representation
    self.child.to_representation(item) for item in iterable
  File "/root/Envs/TS/lib/python3.5/site-packages/rest_framework/serializers.py", line 683, in <listcomp>
    self.child.to_representation(item) for item in iterable
  File "/root/Envs/TS/lib/python3.5/site-packages/rest_framework/serializers.py", line 510, in to_representation
    fields = self._readable_fields
  File "/root/Envs/TS/lib/python3.5/site-packages/django/utils/functional.py", line 35, in __get__
    res = instance.__dict__[self.name] = self.func(instance)
  File "/root/Envs/TS/lib/python3.5/site-packages/rest_framework/serializers.py", line 376, in _readable_fields
    field for field in self.fields.values()
  File "/root/Envs/TS/lib/python3.5/site-packages/rest_framework/serializers.py", line 364, in fields
    self._fields[key] = value
  File "/root/Envs/TS/lib/python3.5/site-packages/rest_framework/utils/serializer_helpers.py", line 148, in __setitem__
    field.bind(field_name=key, parent=self.serializer)
  File "/root/Envs/TS/lib/python3.5/site-packages/rest_framework/fields.py", line 385, in bind
    self.source_attrs = self.source.split('.')
AttributeError: 'int' object has no attribute 'split'
2018-08-15 10:31:44,066 - exception.py[line:135] - ERROR: Internal Server Error: /spiderkingdom/api/domains/
Traceback (most recent call last):
  File "/root/Envs/TS/lib/python3.5/site-packages/django/core/handlers/exception.py", line 41, in inner
    response = get_response(request)
  File "/root/Envs/TS/lib/python3.5/site-packages/django/core/handlers/base.py", line 187, in _get_response
    response = self.process_exception_by_middleware(e, request)
  File "/root/Envs/TS/lib/python3.5/site-packages/django/core/handlers/base.py", line 185, in _get_response
    response = wrapped_callback(request, *callback_args, **callback_kwargs)
  File "/root/Envs/TS/lib/python3.5/site-packages/django/views/decorators/csrf.py", line 58, in wrapped_view
    return view_func(*args, **kwargs)
  File "/root/Envs/TS/lib/python3.5/site-packages/rest_framework/viewsets.py", line 103, in view
    return self.dispatch(request, *args, **kwargs)
  File "/root/Envs/TS/lib/python3.5/site-packages/rest_framework/views.py", line 483, in dispatch
    response = self.handle_exception(exc)
  File "/root/Envs/TS/lib/python3.5/site-packages/rest_framework/views.py", line 443, in handle_exception
    self.raise_uncaught_exception(exc)
  File "/root/Envs/TS/lib/python3.5/site-packages/rest_framework/views.py", line 480, in dispatch
    response = handler(request, *args, **kwargs)
  File "/root/Envs/TS/lib/python3.5/site-packages/rest_framework/mixins.py", line 45, in list
    return self.get_paginated_response(serializer.data)
  File "/root/Envs/TS/lib/python3.5/site-packages/rest_framework/serializers.py", line 765, in data
    ret = super(ListSerializer, self).data
  File "/root/Envs/TS/lib/python3.5/site-packages/rest_framework/serializers.py", line 262, in data
    self._data = self.to_representation(self.instance)
  File "/root/Envs/TS/lib/python3.5/site-packages/rest_framework/serializers.py", line 683, in to_representation
    self.child.to_representation(item) for item in iterable
  File "/root/Envs/TS/lib/python3.5/site-packages/rest_framework/serializers.py", line 683, in <listcomp>
    self.child.to_representation(item) for item in iterable
  File "/root/Envs/TS/lib/python3.5/site-packages/rest_framework/serializers.py", line 510, in to_representation
    fields = self._readable_fields
  File "/root/Envs/TS/lib/python3.5/site-packages/django/utils/functional.py", line 35, in __get__
    res = instance.__dict__[self.name] = self.func(instance)
  File "/root/Envs/TS/lib/python3.5/site-packages/rest_framework/serializers.py", line 376, in _readable_fields
    field for field in self.fields.values()
  File "/root/Envs/TS/lib/python3.5/site-packages/rest_framework/serializers.py", line 364, in fields
    self._fields[key] = value
  File "/root/Envs/TS/lib/python3.5/site-packages/rest_framework/utils/serializer_helpers.py", line 148, in __setitem__
    field.bind(field_name=key, parent=self.serializer)
  File "/root/Envs/TS/lib/python3.5/site-packages/rest_framework/fields.py", line 385, in bind
    self.source_attrs = self.source.split('.')
AttributeError: 'int' object has no attribute 'split'
2018-08-15 10:49:18,076 - exception.py[line:135] - ERROR: Internal Server Error: /spiderkingdom/api/domains/
Traceback (most recent call last):
  File "/root/Envs/TS/lib/python3.5/site-packages/django/core/handlers/exception.py", line 41, in inner
    response = get_response(request)
  File "/root/Envs/TS/lib/python3.5/site-packages/django/core/handlers/base.py", line 187, in _get_response
    response = self.process_exception_by_middleware(e, request)
  File "/root/Envs/TS/lib/python3.5/site-packages/django/core/handlers/base.py", line 185, in _get_response
    response = wrapped_callback(request, *callback_args, **callback_kwargs)
  File "/root/Envs/TS/lib/python3.5/site-packages/django/views/decorators/csrf.py", line 58, in wrapped_view
    return view_func(*args, **kwargs)
  File "/root/Envs/TS/lib/python3.5/site-packages/rest_framework/viewsets.py", line 103, in view
    return self.dispatch(request, *args, **kwargs)
  File "/root/Envs/TS/lib/python3.5/site-packages/rest_framework/views.py", line 483, in dispatch
    response = self.handle_exception(exc)
  File "/root/Envs/TS/lib/python3.5/site-packages/rest_framework/views.py", line 443, in handle_exception
    self.raise_uncaught_exception(exc)
  File "/root/Envs/TS/lib/python3.5/site-packages/rest_framework/views.py", line 480, in dispatch
    response = handler(request, *args, **kwargs)
  File "/root/Envs/TS/lib/python3.5/site-packages/rest_framework/mixins.py", line 45, in list
    return self.get_paginated_response(serializer.data)
  File "/root/Envs/TS/lib/python3.5/site-packages/rest_framework/serializers.py", line 765, in data
    ret = super(ListSerializer, self).data
  File "/root/Envs/TS/lib/python3.5/site-packages/rest_framework/serializers.py", line 262, in data
    self._data = self.to_representation(self.instance)
  File "/root/Envs/TS/lib/python3.5/site-packages/rest_framework/serializers.py", line 683, in to_representation
    self.child.to_representation(item) for item in iterable
  File "/root/Envs/TS/lib/python3.5/site-packages/rest_framework/serializers.py", line 683, in <listcomp>
    self.child.to_representation(item) for item in iterable
  File "/root/Envs/TS/lib/python3.5/site-packages/rest_framework/serializers.py", line 510, in to_representation
    fields = self._readable_fields
  File "/root/Envs/TS/lib/python3.5/site-packages/django/utils/functional.py", line 35, in __get__
    res = instance.__dict__[self.name] = self.func(instance)
  File "/root/Envs/TS/lib/python3.5/site-packages/rest_framework/serializers.py", line 376, in _readable_fields
    field for field in self.fields.values()
  File "/root/Envs/TS/lib/python3.5/site-packages/rest_framework/serializers.py", line 363, in fields
    for key, value in self.get_fields().items():
  File "/root/Envs/TS/lib/python3.5/site-packages/rest_framework/serializers.py", line 1026, in get_fields
    field_names, declared_fields, extra_kwargs
  File "/root/Envs/TS/lib/python3.5/site-packages/rest_framework/serializers.py", line 1373, in get_uniqueness_extra_kwargs
    field_names, declared_fields, extra_kwargs
  File "/root/Envs/TS/lib/python3.5/site-packages/rest_framework/serializers.py", line 1451, in _get_model_fields
    source = extra_kwargs[field_name]['source']
TypeError: 'int' object is not subscriptable
2018-08-15 10:50:23,883 - exception.py[line:135] - ERROR: Internal Server Error: /spiderkingdom/api/domains/
Traceback (most recent call last):
  File "/root/Envs/TS/lib/python3.5/site-packages/django/core/handlers/exception.py", line 41, in inner
    response = get_response(request)
  File "/root/Envs/TS/lib/python3.5/site-packages/django/core/handlers/base.py", line 187, in _get_response
    response = self.process_exception_by_middleware(e, request)
  File "/root/Envs/TS/lib/python3.5/site-packages/django/core/handlers/base.py", line 185, in _get_response
    response = wrapped_callback(request, *callback_args, **callback_kwargs)
  File "/root/Envs/TS/lib/python3.5/site-packages/django/views/decorators/csrf.py", line 58, in wrapped_view
    return view_func(*args, **kwargs)
  File "/root/Envs/TS/lib/python3.5/site-packages/rest_framework/viewsets.py", line 103, in view
    return self.dispatch(request, *args, **kwargs)
  File "/root/Envs/TS/lib/python3.5/site-packages/rest_framework/views.py", line 483, in dispatch
    response = self.handle_exception(exc)
  File "/root/Envs/TS/lib/python3.5/site-packages/rest_framework/views.py", line 443, in handle_exception
    self.raise_uncaught_exception(exc)
  File "/root/Envs/TS/lib/python3.5/site-packages/rest_framework/views.py", line 480, in dispatch
    response = handler(request, *args, **kwargs)
  File "/root/Envs/TS/lib/python3.5/site-packages/rest_framework/mixins.py", line 45, in list
    return self.get_paginated_response(serializer.data)
  File "/root/Envs/TS/lib/python3.5/site-packages/rest_framework/serializers.py", line 765, in data
    ret = super(ListSerializer, self).data
  File "/root/Envs/TS/lib/python3.5/site-packages/rest_framework/serializers.py", line 262, in data
    self._data = self.to_representation(self.instance)
  File "/root/Envs/TS/lib/python3.5/site-packages/rest_framework/serializers.py", line 683, in to_representation
    self.child.to_representation(item) for item in iterable
  File "/root/Envs/TS/lib/python3.5/site-packages/rest_framework/serializers.py", line 683, in <listcomp>
    self.child.to_representation(item) for item in iterable
  File "/root/Envs/TS/lib/python3.5/site-packages/rest_framework/serializers.py", line 510, in to_representation
    fields = self._readable_fields
  File "/root/Envs/TS/lib/python3.5/site-packages/django/utils/functional.py", line 35, in __get__
    res = instance.__dict__[self.name] = self.func(instance)
  File "/root/Envs/TS/lib/python3.5/site-packages/rest_framework/serializers.py", line 376, in _readable_fields
    field for field in self.fields.values()
  File "/root/Envs/TS/lib/python3.5/site-packages/rest_framework/serializers.py", line 363, in fields
    for key, value in self.get_fields().items():
  File "/root/Envs/TS/lib/python3.5/site-packages/rest_framework/serializers.py", line 1026, in get_fields
    field_names, declared_fields, extra_kwargs
  File "/root/Envs/TS/lib/python3.5/site-packages/rest_framework/serializers.py", line 1373, in get_uniqueness_extra_kwargs
    field_names, declared_fields, extra_kwargs
  File "/root/Envs/TS/lib/python3.5/site-packages/rest_framework/serializers.py", line 1451, in _get_model_fields
    source = extra_kwargs[field_name]['source']
  File "/root/Envs/TS/lib/python3.5/site-packages/django/db/models/query.py", line 265, in __getitem__
    raise TypeError
TypeError
2018-08-15 10:51:15,462 - exception.py[line:135] - ERROR: Internal Server Error: /spiderkingdom/api/domains/
Traceback (most recent call last):
  File "/root/Envs/TS/lib/python3.5/site-packages/django/core/handlers/exception.py", line 41, in inner
    response = get_response(request)
  File "/root/Envs/TS/lib/python3.5/site-packages/django/core/handlers/base.py", line 187, in _get_response
    response = self.process_exception_by_middleware(e, request)
  File "/root/Envs/TS/lib/python3.5/site-packages/django/core/handlers/base.py", line 185, in _get_response
    response = wrapped_callback(request, *callback_args, **callback_kwargs)
  File "/root/Envs/TS/lib/python3.5/site-packages/django/views/decorators/csrf.py", line 58, in wrapped_view
    return view_func(*args, **kwargs)
  File "/root/Envs/TS/lib/python3.5/site-packages/rest_framework/viewsets.py", line 103, in view
    return self.dispatch(request, *args, **kwargs)
  File "/root/Envs/TS/lib/python3.5/site-packages/rest_framework/views.py", line 483, in dispatch
    response = self.handle_exception(exc)
  File "/root/Envs/TS/lib/python3.5/site-packages/rest_framework/views.py", line 443, in handle_exception
    self.raise_uncaught_exception(exc)
  File "/root/Envs/TS/lib/python3.5/site-packages/rest_framework/views.py", line 480, in dispatch
    response = handler(request, *args, **kwargs)
  File "/root/Envs/TS/lib/python3.5/site-packages/rest_framework/mixins.py", line 45, in list
    return self.get_paginated_response(serializer.data)
  File "/root/Envs/TS/lib/python3.5/site-packages/rest_framework/serializers.py", line 765, in data
    ret = super(ListSerializer, self).data
  File "/root/Envs/TS/lib/python3.5/site-packages/rest_framework/serializers.py", line 262, in data
    self._data = self.to_representation(self.instance)
  File "/root/Envs/TS/lib/python3.5/site-packages/rest_framework/serializers.py", line 683, in to_representation
    self.child.to_representation(item) for item in iterable
  File "/root/Envs/TS/lib/python3.5/site-packages/rest_framework/serializers.py", line 683, in <listcomp>
    self.child.to_representation(item) for item in iterable
  File "/root/Envs/TS/lib/python3.5/site-packages/rest_framework/serializers.py", line 510, in to_representation
    fields = self._readable_fields
  File "/root/Envs/TS/lib/python3.5/site-packages/django/utils/functional.py", line 35, in __get__
    res = instance.__dict__[self.name] = self.func(instance)
  File "/root/Envs/TS/lib/python3.5/site-packages/rest_framework/serializers.py", line 376, in _readable_fields
    field for field in self.fields.values()
  File "/root/Envs/TS/lib/python3.5/site-packages/rest_framework/serializers.py", line 363, in fields
    for key, value in self.get_fields().items():
  File "/root/Envs/TS/lib/python3.5/site-packages/rest_framework/serializers.py", line 1024, in get_fields
    extra_kwargs = self.get_extra_kwargs()
  File "/root/Envs/TS/lib/python3.5/site-packages/rest_framework/serializers.py", line 1346, in get_extra_kwargs
    kwargs['read_only'] = True
TypeError: 'int' object does not support item assignment
2018-08-15 10:51:51,713 - exception.py[line:135] - ERROR: Internal Server Error: /spiderkingdom/api/domains/
Traceback (most recent call last):
  File "/root/Envs/TS/lib/python3.5/site-packages/django/core/handlers/exception.py", line 41, in inner
    response = get_response(request)
  File "/root/Envs/TS/lib/python3.5/site-packages/django/core/handlers/base.py", line 187, in _get_response
    response = self.process_exception_by_middleware(e, request)
  File "/root/Envs/TS/lib/python3.5/site-packages/django/core/handlers/base.py", line 185, in _get_response
    response = wrapped_callback(request, *callback_args, **callback_kwargs)
  File "/root/Envs/TS/lib/python3.5/site-packages/django/views/decorators/csrf.py", line 58, in wrapped_view
    return view_func(*args, **kwargs)
  File "/root/Envs/TS/lib/python3.5/site-packages/rest_framework/viewsets.py", line 103, in view
    return self.dispatch(request, *args, **kwargs)
  File "/root/Envs/TS/lib/python3.5/site-packages/rest_framework/views.py", line 483, in dispatch
    response = self.handle_exception(exc)
  File "/root/Envs/TS/lib/python3.5/site-packages/rest_framework/views.py", line 443, in handle_exception
    self.raise_uncaught_exception(exc)
  File "/root/Envs/TS/lib/python3.5/site-packages/rest_framework/views.py", line 480, in dispatch
    response = handler(request, *args, **kwargs)
  File "/root/Envs/TS/lib/python3.5/site-packages/rest_framework/mixins.py", line 45, in list
    return self.get_paginated_response(serializer.data)
  File "/root/Envs/TS/lib/python3.5/site-packages/rest_framework/serializers.py", line 765, in data
    ret = super(ListSerializer, self).data
  File "/root/Envs/TS/lib/python3.5/site-packages/rest_framework/serializers.py", line 262, in data
    self._data = self.to_representation(self.instance)
  File "/root/Envs/TS/lib/python3.5/site-packages/rest_framework/serializers.py", line 683, in to_representation
    self.child.to_representation(item) for item in iterable
  File "/root/Envs/TS/lib/python3.5/site-packages/rest_framework/serializers.py", line 683, in <listcomp>
    self.child.to_representation(item) for item in iterable
  File "/root/Envs/TS/lib/python3.5/site-packages/rest_framework/serializers.py", line 510, in to_representation
    fields = self._readable_fields
  File "/root/Envs/TS/lib/python3.5/site-packages/django/utils/functional.py", line 35, in __get__
    res = instance.__dict__[self.name] = self.func(instance)
  File "/root/Envs/TS/lib/python3.5/site-packages/rest_framework/serializers.py", line 376, in _readable_fields
    field for field in self.fields.values()
  File "/root/Envs/TS/lib/python3.5/site-packages/rest_framework/serializers.py", line 363, in fields
    for key, value in self.get_fields().items():
  File "/root/Envs/TS/lib/python3.5/site-packages/rest_framework/serializers.py", line 1024, in get_fields
    extra_kwargs = self.get_extra_kwargs()
  File "/root/Envs/TS/lib/python3.5/site-packages/rest_framework/serializers.py", line 1346, in get_extra_kwargs
    kwargs['read_only'] = True
TypeError: 'int' object does not support item assignment
2018-08-15 10:52:11,649 - exception.py[line:135] - ERROR: Internal Server Error: /spiderkingdom/api/domains/12/
Traceback (most recent call last):
  File "/root/Envs/TS/lib/python3.5/site-packages/django/core/handlers/exception.py", line 41, in inner
    response = get_response(request)
  File "/root/Envs/TS/lib/python3.5/site-packages/django/core/handlers/base.py", line 187, in _get_response
    response = self.process_exception_by_middleware(e, request)
  File "/root/Envs/TS/lib/python3.5/site-packages/django/core/handlers/base.py", line 185, in _get_response
    response = wrapped_callback(request, *callback_args, **callback_kwargs)
  File "/root/Envs/TS/lib/python3.5/site-packages/django/views/decorators/csrf.py", line 58, in wrapped_view
    return view_func(*args, **kwargs)
  File "/root/Envs/TS/lib/python3.5/site-packages/rest_framework/viewsets.py", line 103, in view
    return self.dispatch(request, *args, **kwargs)
  File "/root/Envs/TS/lib/python3.5/site-packages/rest_framework/views.py", line 483, in dispatch
    response = self.handle_exception(exc)
  File "/root/Envs/TS/lib/python3.5/site-packages/rest_framework/views.py", line 443, in handle_exception
    self.raise_uncaught_exception(exc)
  File "/root/Envs/TS/lib/python3.5/site-packages/rest_framework/views.py", line 480, in dispatch
    response = handler(request, *args, **kwargs)
  File "/root/Envs/TS/lib/python3.5/site-packages/rest_framework/mixins.py", line 58, in retrieve
    return Response(serializer.data)
  File "/root/Envs/TS/lib/python3.5/site-packages/rest_framework/serializers.py", line 560, in data
    ret = super(Serializer, self).data
  File "/root/Envs/TS/lib/python3.5/site-packages/rest_framework/serializers.py", line 262, in data
    self._data = self.to_representation(self.instance)
  File "/root/Envs/TS/lib/python3.5/site-packages/rest_framework/serializers.py", line 510, in to_representation
    fields = self._readable_fields
  File "/root/Envs/TS/lib/python3.5/site-packages/django/utils/functional.py", line 35, in __get__
    res = instance.__dict__[self.name] = self.func(instance)
  File "/root/Envs/TS/lib/python3.5/site-packages/rest_framework/serializers.py", line 376, in _readable_fields
    field for field in self.fields.values()
  File "/root/Envs/TS/lib/python3.5/site-packages/rest_framework/serializers.py", line 363, in fields
    for key, value in self.get_fields().items():
  File "/root/Envs/TS/lib/python3.5/site-packages/rest_framework/serializers.py", line 1024, in get_fields
    extra_kwargs = self.get_extra_kwargs()
  File "/root/Envs/TS/lib/python3.5/site-packages/rest_framework/serializers.py", line 1346, in get_extra_kwargs
    kwargs['read_only'] = True
TypeError: 'int' object does not support item assignment
2018-08-15 11:22:23,564 - base.py[line:152] - WARNING: Not Found: /favicon.ico
2018-08-15 13:29:12,373 - exception.py[line:135] - ERROR: Internal Server Error: /spiderkingdom/api/domains/
Traceback (most recent call last):
  File "/root/Envs/TS/lib/python3.5/site-packages/django/core/handlers/exception.py", line 41, in inner
    response = get_response(request)
  File "/root/Envs/TS/lib/python3.5/site-packages/django/core/handlers/base.py", line 187, in _get_response
    response = self.process_exception_by_middleware(e, request)
  File "/root/Envs/TS/lib/python3.5/site-packages/django/core/handlers/base.py", line 185, in _get_response
    response = wrapped_callback(request, *callback_args, **callback_kwargs)
  File "/root/Envs/TS/lib/python3.5/site-packages/django/views/decorators/csrf.py", line 58, in wrapped_view
    return view_func(*args, **kwargs)
  File "/root/Envs/TS/lib/python3.5/site-packages/rest_framework/viewsets.py", line 103, in view
    return self.dispatch(request, *args, **kwargs)
  File "/root/Envs/TS/lib/python3.5/site-packages/rest_framework/views.py", line 483, in dispatch
    response = self.handle_exception(exc)
  File "/root/Envs/TS/lib/python3.5/site-packages/rest_framework/views.py", line 443, in handle_exception
    self.raise_uncaught_exception(exc)
  File "/root/Envs/TS/lib/python3.5/site-packages/rest_framework/views.py", line 480, in dispatch
    response = handler(request, *args, **kwargs)
  File "/opt/TS/SpiderKingdom/views.py", line 73, in list
    queryset = self.filter_queryset(self.get_queryset())
  File "/root/Envs/TS/lib/python3.5/site-packages/rest_framework/generics.py", line 152, in filter_queryset
    queryset = backend().filter_queryset(self.request, queryset, self)
TypeError: filter_queryset() takes 2 positional arguments but 4 were given
2018-08-15 13:29:18,389 - exception.py[line:135] - ERROR: Internal Server Error: /spiderkingdom/api/domains/
Traceback (most recent call last):
  File "/root/Envs/TS/lib/python3.5/site-packages/django/core/handlers/exception.py", line 41, in inner
    response = get_response(request)
  File "/root/Envs/TS/lib/python3.5/site-packages/django/core/handlers/base.py", line 187, in _get_response
    response = self.process_exception_by_middleware(e, request)
  File "/root/Envs/TS/lib/python3.5/site-packages/django/core/handlers/base.py", line 185, in _get_response
    response = wrapped_callback(request, *callback_args, **callback_kwargs)
  File "/root/Envs/TS/lib/python3.5/site-packages/django/views/decorators/csrf.py", line 58, in wrapped_view
    return view_func(*args, **kwargs)
  File "/root/Envs/TS/lib/python3.5/site-packages/rest_framework/viewsets.py", line 103, in view
    return self.dispatch(request, *args, **kwargs)
  File "/root/Envs/TS/lib/python3.5/site-packages/rest_framework/views.py", line 483, in dispatch
    response = self.handle_exception(exc)
  File "/root/Envs/TS/lib/python3.5/site-packages/rest_framework/views.py", line 443, in handle_exception
    self.raise_uncaught_exception(exc)
  File "/root/Envs/TS/lib/python3.5/site-packages/rest_framework/views.py", line 480, in dispatch
    response = handler(request, *args, **kwargs)
  File "/opt/TS/SpiderKingdom/views.py", line 73, in list
    queryset = self.filter_queryset(self.get_queryset())
  File "/root/Envs/TS/lib/python3.5/site-packages/rest_framework/generics.py", line 152, in filter_queryset
    queryset = backend().filter_queryset(self.request, queryset, self)
TypeError: filter_queryset() takes 2 positional arguments but 4 were given
2018-08-15 13:29:41,805 - exception.py[line:135] - ERROR: Internal Server Error: /spiderkingdom/api/domains/
Traceback (most recent call last):
  File "/root/Envs/TS/lib/python3.5/site-packages/django/core/handlers/exception.py", line 41, in inner
    response = get_response(request)
  File "/root/Envs/TS/lib/python3.5/site-packages/django/core/handlers/base.py", line 187, in _get_response
    response = self.process_exception_by_middleware(e, request)
  File "/root/Envs/TS/lib/python3.5/site-packages/django/core/handlers/base.py", line 185, in _get_response
    response = wrapped_callback(request, *callback_args, **callback_kwargs)
  File "/root/Envs/TS/lib/python3.5/site-packages/django/views/decorators/csrf.py", line 58, in wrapped_view
    return view_func(*args, **kwargs)
  File "/root/Envs/TS/lib/python3.5/site-packages/rest_framework/viewsets.py", line 103, in view
    return self.dispatch(request, *args, **kwargs)
  File "/root/Envs/TS/lib/python3.5/site-packages/rest_framework/views.py", line 483, in dispatch
    response = self.handle_exception(exc)
  File "/root/Envs/TS/lib/python3.5/site-packages/rest_framework/views.py", line 443, in handle_exception
    self.raise_uncaught_exception(exc)
  File "/root/Envs/TS/lib/python3.5/site-packages/rest_framework/views.py", line 480, in dispatch
    response = handler(request, *args, **kwargs)
  File "/opt/TS/SpiderKingdom/views.py", line 73, in list
    queryset = self.filter_queryset(self.get_queryset())
  File "/root/Envs/TS/lib/python3.5/site-packages/rest_framework/generics.py", line 152, in filter_queryset
    queryset = backend().filter_queryset(self.request, queryset, self)
TypeError: filter_queryset() takes 2 positional arguments but 4 were given
2018-08-15 13:30:31,363 - exception.py[line:135] - ERROR: Internal Server Error: /spiderkingdom/api/domains/
Traceback (most recent call last):
  File "/root/Envs/TS/lib/python3.5/site-packages/django/core/handlers/exception.py", line 41, in inner
    response = get_response(request)
  File "/root/Envs/TS/lib/python3.5/site-packages/django/core/handlers/base.py", line 187, in _get_response
    response = self.process_exception_by_middleware(e, request)
  File "/root/Envs/TS/lib/python3.5/site-packages/django/core/handlers/base.py", line 185, in _get_response
    response = wrapped_callback(request, *callback_args, **callback_kwargs)
  File "/root/Envs/TS/lib/python3.5/site-packages/django/views/decorators/csrf.py", line 58, in wrapped_view
    return view_func(*args, **kwargs)
  File "/root/Envs/TS/lib/python3.5/site-packages/rest_framework/viewsets.py", line 103, in view
    return self.dispatch(request, *args, **kwargs)
  File "/root/Envs/TS/lib/python3.5/site-packages/rest_framework/views.py", line 483, in dispatch
    response = self.handle_exception(exc)
  File "/root/Envs/TS/lib/python3.5/site-packages/rest_framework/views.py", line 443, in handle_exception
    self.raise_uncaught_exception(exc)
  File "/root/Envs/TS/lib/python3.5/site-packages/rest_framework/views.py", line 480, in dispatch
    response = handler(request, *args, **kwargs)
  File "/opt/TS/SpiderKingdom/views.py", line 73, in list
    queryset = self.filter_queryset(self.get_queryset())
  File "/root/Envs/TS/lib/python3.5/site-packages/rest_framework/generics.py", line 152, in filter_queryset
    queryset = backend().filter_queryset(self.request, queryset, self)
TypeError: filter_queryset() takes 2 positional arguments but 4 were given
2018-08-15 13:46:43,862 - exception.py[line:135] - ERROR: Internal Server Error: /spiderkingdom/api/domains/
Traceback (most recent call last):
  File "/root/Envs/TS/lib/python3.5/site-packages/django/core/handlers/exception.py", line 41, in inner
    response = get_response(request)
  File "/root/Envs/TS/lib/python3.5/site-packages/django/core/handlers/base.py", line 187, in _get_response
    response = self.process_exception_by_middleware(e, request)
  File "/root/Envs/TS/lib/python3.5/site-packages/django/core/handlers/base.py", line 185, in _get_response
    response = wrapped_callback(request, *callback_args, **callback_kwargs)
  File "/root/Envs/TS/lib/python3.5/site-packages/django/views/decorators/csrf.py", line 58, in wrapped_view
    return view_func(*args, **kwargs)
  File "/root/Envs/TS/lib/python3.5/site-packages/rest_framework/viewsets.py", line 103, in view
    return self.dispatch(request, *args, **kwargs)
  File "/root/Envs/TS/lib/python3.5/site-packages/rest_framework/views.py", line 483, in dispatch
    response = self.handle_exception(exc)
  File "/root/Envs/TS/lib/python3.5/site-packages/rest_framework/views.py", line 443, in handle_exception
    self.raise_uncaught_exception(exc)
  File "/root/Envs/TS/lib/python3.5/site-packages/rest_framework/views.py", line 480, in dispatch
    response = handler(request, *args, **kwargs)
  File "/opt/TS/SpiderKingdom/views.py", line 73, in list
    queryset = self.filter_queryset(self.get_queryset())
  File "/root/Envs/TS/lib/python3.5/site-packages/rest_framework/generics.py", line 152, in filter_queryset
    queryset = backend().filter_queryset(self.request, queryset, self)
  File "/root/Envs/TS/lib/python3.5/site-packages/django_filters/rest_framework/backends.py", line 96, in filter_queryset
    return filterset.qs
  File "/root/Envs/TS/lib/python3.5/site-packages/django_filters/filterset.py", line 237, in qs
    qs = self.filter_queryset(qs)
  File "/root/Envs/TS/lib/python3.5/site-packages/django_filters/filterset.py", line 224, in filter_queryset
    queryset = self.filters[name].filter(queryset, value)
  File "/root/Envs/TS/lib/python3.5/site-packages/django_filters/filters.py", line 147, in filter
    qs = self.get_method(qs)(**{lookup: value})
  File "/root/Envs/TS/lib/python3.5/site-packages/django/db/models/query.py", line 781, in filter
    return self._filter_or_exclude(False, *args, **kwargs)
  File "/root/Envs/TS/lib/python3.5/site-packages/django/db/models/query.py", line 799, in _filter_or_exclude
    clone.query.add_q(Q(*args, **kwargs))
  File "/root/Envs/TS/lib/python3.5/site-packages/django/db/models/sql/query.py", line 1260, in add_q
    clause, _ = self._add_q(q_object, self.used_aliases)
  File "/root/Envs/TS/lib/python3.5/site-packages/django/db/models/sql/query.py", line 1286, in _add_q
    allow_joins=allow_joins, split_subq=split_subq,
  File "/root/Envs/TS/lib/python3.5/site-packages/django/db/models/sql/query.py", line 1220, in build_filter
    condition = self.build_lookup(lookups, col, value)
  File "/root/Envs/TS/lib/python3.5/site-packages/django/db/models/sql/query.py", line 1112, in build_lookup
    lhs = self.try_transform(lhs, name, lookups)
  File "/root/Envs/TS/lib/python3.5/site-packages/django/db/models/sql/query.py", line 1130, in try_transform
    (name, lhs.output_field.__class__.__name__))
django.core.exceptions.FieldError: Unsupported lookup '=' for BooleanField or join on the field not permitted.
2018-08-15 13:46:58,328 - exception.py[line:135] - ERROR: Internal Server Error: /spiderkingdom/api/domains/
Traceback (most recent call last):
  File "/root/Envs/TS/lib/python3.5/site-packages/django/core/handlers/exception.py", line 41, in inner
    response = get_response(request)
  File "/root/Envs/TS/lib/python3.5/site-packages/django/core/handlers/base.py", line 187, in _get_response
    response = self.process_exception_by_middleware(e, request)
  File "/root/Envs/TS/lib/python3.5/site-packages/django/core/handlers/base.py", line 185, in _get_response
    response = wrapped_callback(request, *callback_args, **callback_kwargs)
  File "/root/Envs/TS/lib/python3.5/site-packages/django/views/decorators/csrf.py", line 58, in wrapped_view
    return view_func(*args, **kwargs)
  File "/root/Envs/TS/lib/python3.5/site-packages/rest_framework/viewsets.py", line 103, in view
    return self.dispatch(request, *args, **kwargs)
  File "/root/Envs/TS/lib/python3.5/site-packages/rest_framework/views.py", line 483, in dispatch
    response = self.handle_exception(exc)
  File "/root/Envs/TS/lib/python3.5/site-packages/rest_framework/views.py", line 443, in handle_exception
    self.raise_uncaught_exception(exc)
  File "/root/Envs/TS/lib/python3.5/site-packages/rest_framework/views.py", line 480, in dispatch
    response = handler(request, *args, **kwargs)
  File "/opt/TS/SpiderKingdom/views.py", line 73, in list
    queryset = self.filter_queryset(self.get_queryset())
  File "/root/Envs/TS/lib/python3.5/site-packages/rest_framework/generics.py", line 152, in filter_queryset
    queryset = backend().filter_queryset(self.request, queryset, self)
  File "/root/Envs/TS/lib/python3.5/site-packages/django_filters/rest_framework/backends.py", line 96, in filter_queryset
    return filterset.qs
  File "/root/Envs/TS/lib/python3.5/site-packages/django_filters/filterset.py", line 237, in qs
    qs = self.filter_queryset(qs)
  File "/root/Envs/TS/lib/python3.5/site-packages/django_filters/filterset.py", line 224, in filter_queryset
    queryset = self.filters[name].filter(queryset, value)
  File "/root/Envs/TS/lib/python3.5/site-packages/django_filters/filters.py", line 147, in filter
    qs = self.get_method(qs)(**{lookup: value})
  File "/root/Envs/TS/lib/python3.5/site-packages/django/db/models/query.py", line 781, in filter
    return self._filter_or_exclude(False, *args, **kwargs)
  File "/root/Envs/TS/lib/python3.5/site-packages/django/db/models/query.py", line 799, in _filter_or_exclude
    clone.query.add_q(Q(*args, **kwargs))
  File "/root/Envs/TS/lib/python3.5/site-packages/django/db/models/sql/query.py", line 1260, in add_q
    clause, _ = self._add_q(q_object, self.used_aliases)
  File "/root/Envs/TS/lib/python3.5/site-packages/django/db/models/sql/query.py", line 1286, in _add_q
    allow_joins=allow_joins, split_subq=split_subq,
  File "/root/Envs/TS/lib/python3.5/site-packages/django/db/models/sql/query.py", line 1220, in build_filter
    condition = self.build_lookup(lookups, col, value)
  File "/root/Envs/TS/lib/python3.5/site-packages/django/db/models/sql/query.py", line 1112, in build_lookup
    lhs = self.try_transform(lhs, name, lookups)
  File "/root/Envs/TS/lib/python3.5/site-packages/django/db/models/sql/query.py", line 1130, in try_transform
    (name, lhs.output_field.__class__.__name__))
django.core.exceptions.FieldError: Unsupported lookup 'eq' for BooleanField or join on the field not permitted.
2018-08-15 14:08:12,331 - exception.py[line:135] - ERROR: Internal Server Error: /spiderkingdom/api/domains/
Traceback (most recent call last):
  File "/root/Envs/TS/lib/python3.5/site-packages/django/core/handlers/exception.py", line 41, in inner
    response = get_response(request)
  File "/root/Envs/TS/lib/python3.5/site-packages/django/core/handlers/base.py", line 217, in _get_response
    response = self.process_exception_by_middleware(e, request)
  File "/root/Envs/TS/lib/python3.5/site-packages/django/core/handlers/base.py", line 215, in _get_response
    response = response.render()
  File "/root/Envs/TS/lib/python3.5/site-packages/django/template/response.py", line 107, in render
    self.content = self.rendered_content
  File "/root/Envs/TS/lib/python3.5/site-packages/rest_framework/response.py", line 72, in rendered_content
    ret = renderer.render(self.data, accepted_media_type, context)
  File "/root/Envs/TS/lib/python3.5/site-packages/rest_framework/renderers.py", line 105, in render
    allow_nan=not self.strict, separators=separators
  File "/root/Envs/TS/lib/python3.5/site-packages/rest_framework/utils/json.py", line 28, in dumps
    return json.dumps(*args, **kwargs)
  File "/usr/local/python3/lib/python3.5/json/__init__.py", line 237, in dumps
    **kw).encode(obj)
  File "/usr/local/python3/lib/python3.5/json/encoder.py", line 198, in encode
    chunks = self.iterencode(o, _one_shot=True)
  File "/usr/local/python3/lib/python3.5/json/encoder.py", line 256, in iterencode
    return _iterencode(o, 0)
  File "/root/Envs/TS/lib/python3.5/site-packages/rest_framework/utils/encoders.py", line 68, in default
    return super(JSONEncoder, self).default(obj)
  File "/usr/local/python3/lib/python3.5/json/encoder.py", line 179, in default
    raise TypeError(repr(o) + " is not JSON serializable")
TypeError: <Response status_code=200, "text/html; charset=utf-8"> is not JSON serializable
2018-08-15 14:09:18,569 - exception.py[line:135] - ERROR: Internal Server Error: /spiderkingdom/api/domains/
Traceback (most recent call last):
  File "/root/Envs/TS/lib/python3.5/site-packages/django/core/handlers/exception.py", line 41, in inner
    response = get_response(request)
  File "/root/Envs/TS/lib/python3.5/site-packages/django/core/handlers/base.py", line 187, in _get_response
    response = self.process_exception_by_middleware(e, request)
  File "/root/Envs/TS/lib/python3.5/site-packages/django/core/handlers/base.py", line 185, in _get_response
    response = wrapped_callback(request, *callback_args, **callback_kwargs)
  File "/root/Envs/TS/lib/python3.5/site-packages/django/views/decorators/csrf.py", line 58, in wrapped_view
    return view_func(*args, **kwargs)
  File "/root/Envs/TS/lib/python3.5/site-packages/rest_framework/viewsets.py", line 103, in view
    return self.dispatch(request, *args, **kwargs)
  File "/root/Envs/TS/lib/python3.5/site-packages/rest_framework/views.py", line 483, in dispatch
    response = self.handle_exception(exc)
  File "/root/Envs/TS/lib/python3.5/site-packages/rest_framework/views.py", line 443, in handle_exception
    self.raise_uncaught_exception(exc)
  File "/root/Envs/TS/lib/python3.5/site-packages/rest_framework/views.py", line 480, in dispatch
    response = handler(request, *args, **kwargs)
  File "/opt/TS/SpiderKingdom/views.py", line 94, in list
    'data': json.dumps(self.get_paginated_response(serializer.data)),
  File "/usr/local/python3/lib/python3.5/json/__init__.py", line 230, in dumps
    return _default_encoder.encode(obj)
  File "/usr/local/python3/lib/python3.5/json/encoder.py", line 198, in encode
    chunks = self.iterencode(o, _one_shot=True)
  File "/usr/local/python3/lib/python3.5/json/encoder.py", line 256, in iterencode
    return _iterencode(o, 0)
  File "/usr/local/python3/lib/python3.5/json/encoder.py", line 179, in default
    raise TypeError(repr(o) + " is not JSON serializable")
TypeError: <Response status_code=200, "text/html; charset=utf-8"> is not JSON serializable
2018-08-15 16:56:10,479 - exception.py[line:135] - ERROR: Internal Server Error: /stormwindcity/api/cert_check/sslsechi/
Traceback (most recent call last):
  File "/root/Envs/TS/lib/python3.5/site-packages/django/core/handlers/exception.py", line 41, in inner
    response = get_response(request)
  File "/root/Envs/TS/lib/python3.5/site-packages/django/core/handlers/base.py", line 187, in _get_response
    response = self.process_exception_by_middleware(e, request)
  File "/root/Envs/TS/lib/python3.5/site-packages/django/core/handlers/base.py", line 185, in _get_response
    response = wrapped_callback(request, *callback_args, **callback_kwargs)
  File "/opt/TS/StormwindCity/views.py", line 249, in sslceshi_check
    domain = json.loads(request.body.decode())['domain']
  File "/usr/local/python3/lib/python3.5/json/__init__.py", line 319, in loads
    return _default_decoder.decode(s)
  File "/usr/local/python3/lib/python3.5/json/decoder.py", line 339, in decode
    obj, end = self.raw_decode(s, idx=_w(s, 0).end())
  File "/usr/local/python3/lib/python3.5/json/decoder.py", line 357, in raw_decode
    raise JSONDecodeError("Expecting value", s, err.value) from None
json.decoder.JSONDecodeError: Expecting value: line 1 column 1 (char 0)
2018-08-15 16:57:43,741 - exception.py[line:135] - ERROR: Internal Server Error: /stormwindcity/api/cert_check/sslsechi/
Traceback (most recent call last):
  File "/root/Envs/TS/lib/python3.5/site-packages/django/core/handlers/exception.py", line 41, in inner
    response = get_response(request)
  File "/root/Envs/TS/lib/python3.5/site-packages/django/core/handlers/base.py", line 187, in _get_response
    response = self.process_exception_by_middleware(e, request)
  File "/root/Envs/TS/lib/python3.5/site-packages/django/core/handlers/base.py", line 185, in _get_response
    response = wrapped_callback(request, *callback_args, **callback_kwargs)
  File "/opt/TS/StormwindCity/views.py", line 249, in sslceshi_check
    domain = json.loads(request.body.decode())['domain']
  File "/usr/local/python3/lib/python3.5/json/__init__.py", line 319, in loads
    return _default_decoder.decode(s)
  File "/usr/local/python3/lib/python3.5/json/decoder.py", line 339, in decode
    obj, end = self.raw_decode(s, idx=_w(s, 0).end())
  File "/usr/local/python3/lib/python3.5/json/decoder.py", line 357, in raw_decode
    raise JSONDecodeError("Expecting value", s, err.value) from None
json.decoder.JSONDecodeError: Expecting value: line 1 column 1 (char 0)
2018-08-15 16:58:04,265 - exception.py[line:135] - ERROR: Internal Server Error: /stormwindcity/api/cert_check/sslsechi/
Traceback (most recent call last):
  File "/root/Envs/TS/lib/python3.5/site-packages/django/core/handlers/exception.py", line 41, in inner
    response = get_response(request)
  File "/root/Envs/TS/lib/python3.5/site-packages/django/core/handlers/base.py", line 187, in _get_response
    response = self.process_exception_by_middleware(e, request)
  File "/root/Envs/TS/lib/python3.5/site-packages/django/core/handlers/base.py", line 185, in _get_response
    response = wrapped_callback(request, *callback_args, **callback_kwargs)
  File "/opt/TS/StormwindCity/views.py", line 249, in sslceshi_check
    domain = json.loads(request.body.decode())['domain']
  File "/usr/local/python3/lib/python3.5/json/__init__.py", line 319, in loads
    return _default_decoder.decode(s)
  File "/usr/local/python3/lib/python3.5/json/decoder.py", line 339, in decode
    obj, end = self.raw_decode(s, idx=_w(s, 0).end())
  File "/usr/local/python3/lib/python3.5/json/decoder.py", line 357, in raw_decode
    raise JSONDecodeError("Expecting value", s, err.value) from None
json.decoder.JSONDecodeError: Expecting value: line 1 column 1 (char 0)
2018-08-15 16:58:20,170 - exception.py[line:135] - ERROR: Internal Server Error: /stormwindcity/api/cert_check/sslsechi/
Traceback (most recent call last):
  File "/root/Envs/TS/lib/python3.5/site-packages/django/core/handlers/exception.py", line 41, in inner
    response = get_response(request)
  File "/root/Envs/TS/lib/python3.5/site-packages/django/core/handlers/base.py", line 187, in _get_response
    response = self.process_exception_by_middleware(e, request)
  File "/root/Envs/TS/lib/python3.5/site-packages/django/core/handlers/base.py", line 185, in _get_response
    response = wrapped_callback(request, *callback_args, **callback_kwargs)
  File "/opt/TS/StormwindCity/views.py", line 249, in sslceshi_check
    domain = json.loads(request.body.decode())['domain']
  File "/usr/local/python3/lib/python3.5/json/__init__.py", line 319, in loads
    return _default_decoder.decode(s)
  File "/usr/local/python3/lib/python3.5/json/decoder.py", line 339, in decode
    obj, end = self.raw_decode(s, idx=_w(s, 0).end())
  File "/usr/local/python3/lib/python3.5/json/decoder.py", line 357, in raw_decode
    raise JSONDecodeError("Expecting value", s, err.value) from None
json.decoder.JSONDecodeError: Expecting value: line 1 column 1 (char 0)
2018-08-15 16:59:15,401 - exception.py[line:135] - ERROR: Internal Server Error: /stormwindcity/api/cert_check/sslsechi/
Traceback (most recent call last):
  File "/root/Envs/TS/lib/python3.5/site-packages/django/core/handlers/exception.py", line 41, in inner
    response = get_response(request)
  File "/root/Envs/TS/lib/python3.5/site-packages/django/core/handlers/base.py", line 187, in _get_response
    response = self.process_exception_by_middleware(e, request)
  File "/root/Envs/TS/lib/python3.5/site-packages/django/core/handlers/base.py", line 185, in _get_response
    response = wrapped_callback(request, *callback_args, **callback_kwargs)
  File "/opt/TS/StormwindCity/views.py", line 249, in sslceshi_check
    domain = request.GET.get['domain']
TypeError: 'method' object is not subscriptable
2018-08-15 18:45:45,176 - base.py[line:152] - WARNING: Not Found: /spiderkingdom/api/domains/
2018-08-15 18:46:34,064 - base.py[line:152] - WARNING: Not Found: /spiderkingdom/api/domains/
2018-08-15 18:48:10,009 - base.py[line:152] - WARNING: Not Found: /spiderkingdom/api/domains/
2018-08-15 18:48:53,588 - base.py[line:152] - WARNING: Not Found: /spiderkingdom/api/domains/
2018-08-15 18:53:47,245 - base.py[line:152] - WARNING: Not Found: /spiderkingdom/api/domains/
2018-08-16 09:09:42,181 - base.py[line:152] - WARNING: Not Found: /spiderkingdom/api/domains/
2018-08-16 09:09:44,054 - base.py[line:152] - WARNING: Not Found: /spiderkingdom/api/domains/
2018-08-16 09:45:46,028 - base.py[line:152] - WARNING: Not Found: /spiderkingdom/api/domains/
2018-08-16 14:06:07,662 - exception.py[line:135] - ERROR: Internal Server Error: /spiderkingdom/api/domains/
Traceback (most recent call last):
  File "/root/Envs/TS/lib/python3.5/site-packages/django/core/handlers/exception.py", line 41, in inner
    response = get_response(request)
  File "/root/Envs/TS/lib/python3.5/site-packages/django/core/handlers/base.py", line 187, in _get_response
    response = self.process_exception_by_middleware(e, request)
  File "/root/Envs/TS/lib/python3.5/site-packages/django/core/handlers/base.py", line 185, in _get_response
    response = wrapped_callback(request, *callback_args, **callback_kwargs)
  File "/root/Envs/TS/lib/python3.5/site-packages/django/views/decorators/csrf.py", line 58, in wrapped_view
    return view_func(*args, **kwargs)
  File "/root/Envs/TS/lib/python3.5/site-packages/rest_framework/viewsets.py", line 103, in view
    return self.dispatch(request, *args, **kwargs)
  File "/root/Envs/TS/lib/python3.5/site-packages/rest_framework/views.py", line 483, in dispatch
    response = self.handle_exception(exc)
  File "/root/Envs/TS/lib/python3.5/site-packages/rest_framework/views.py", line 443, in handle_exception
    self.raise_uncaught_exception(exc)
  File "/root/Envs/TS/lib/python3.5/site-packages/rest_framework/views.py", line 480, in dispatch
    response = handler(request, *args, **kwargs)
  File "/opt/TS/SpiderKingdom/views.py", line 107, in create
    self.perform_create(serializer)
  File "/opt/TS/SpiderKingdom/views.py", line 112, in perform_create
    serializer.save()
  File "/root/Envs/TS/lib/python3.5/site-packages/rest_framework/serializers.py", line 184, in save
    'You cannot call `.save()` on a serializer with invalid data.'
AssertionError: You cannot call `.save()` on a serializer with invalid data.
2018-08-16 14:07:22,913 - exception.py[line:135] - ERROR: Internal Server Error: /spiderkingdom/api/domains/
Traceback (most recent call last):
  File "/root/Envs/TS/lib/python3.5/site-packages/django/core/handlers/exception.py", line 41, in inner
    response = get_response(request)
  File "/root/Envs/TS/lib/python3.5/site-packages/django/core/handlers/base.py", line 187, in _get_response
    response = self.process_exception_by_middleware(e, request)
  File "/root/Envs/TS/lib/python3.5/site-packages/django/core/handlers/base.py", line 185, in _get_response
    response = wrapped_callback(request, *callback_args, **callback_kwargs)
  File "/root/Envs/TS/lib/python3.5/site-packages/django/views/decorators/csrf.py", line 58, in wrapped_view
    return view_func(*args, **kwargs)
  File "/root/Envs/TS/lib/python3.5/site-packages/rest_framework/viewsets.py", line 103, in view
    return self.dispatch(request, *args, **kwargs)
  File "/root/Envs/TS/lib/python3.5/site-packages/rest_framework/views.py", line 483, in dispatch
    response = self.handle_exception(exc)
  File "/root/Envs/TS/lib/python3.5/site-packages/rest_framework/views.py", line 443, in handle_exception
    self.raise_uncaught_exception(exc)
  File "/root/Envs/TS/lib/python3.5/site-packages/rest_framework/views.py", line 480, in dispatch
    response = handler(request, *args, **kwargs)
  File "/opt/TS/SpiderKingdom/views.py", line 112, in create
    print(serializer.error)
AttributeError: 'DomainSerializer' object has no attribute 'error'
2018-08-16 14:09:30,892 - exception.py[line:135] - ERROR: Internal Server Error: /spiderkingdom/api/domains/
Traceback (most recent call last):
  File "/root/Envs/TS/lib/python3.5/site-packages/django/core/handlers/exception.py", line 41, in inner
    response = get_response(request)
  File "/root/Envs/TS/lib/python3.5/site-packages/django/core/handlers/base.py", line 187, in _get_response
    response = self.process_exception_by_middleware(e, request)
  File "/root/Envs/TS/lib/python3.5/site-packages/django/core/handlers/base.py", line 185, in _get_response
    response = wrapped_callback(request, *callback_args, **callback_kwargs)
  File "/root/Envs/TS/lib/python3.5/site-packages/django/views/decorators/csrf.py", line 58, in wrapped_view
    return view_func(*args, **kwargs)
  File "/root/Envs/TS/lib/python3.5/site-packages/rest_framework/viewsets.py", line 103, in view
    return self.dispatch(request, *args, **kwargs)
  File "/root/Envs/TS/lib/python3.5/site-packages/rest_framework/views.py", line 485, in dispatch
    self.response = self.finalize_response(request, response, *args, **kwargs)
  File "/root/Envs/TS/lib/python3.5/site-packages/rest_framework/views.py", line 400, in finalize_response
    % type(response)
AssertionError: Expected a `Response`, `HttpResponse` or `HttpStreamingResponse` to be returned from the view, but received a `<class 'NoneType'>`
2018-08-16 14:13:13,652 - exception.py[line:135] - ERROR: Internal Server Error: /spiderkingdom/api/domains/
Traceback (most recent call last):
  File "/root/Envs/TS/lib/python3.5/site-packages/django/core/handlers/exception.py", line 41, in inner
    response = get_response(request)
  File "/root/Envs/TS/lib/python3.5/site-packages/django/core/handlers/base.py", line 187, in _get_response
    response = self.process_exception_by_middleware(e, request)
  File "/root/Envs/TS/lib/python3.5/site-packages/django/core/handlers/base.py", line 185, in _get_response
    response = wrapped_callback(request, *callback_args, **callback_kwargs)
  File "/root/Envs/TS/lib/python3.5/site-packages/django/views/decorators/csrf.py", line 58, in wrapped_view
    return view_func(*args, **kwargs)
  File "/root/Envs/TS/lib/python3.5/site-packages/rest_framework/viewsets.py", line 103, in view
    return self.dispatch(request, *args, **kwargs)
  File "/root/Envs/TS/lib/python3.5/site-packages/rest_framework/views.py", line 485, in dispatch
    self.response = self.finalize_response(request, response, *args, **kwargs)
  File "/root/Envs/TS/lib/python3.5/site-packages/rest_framework/views.py", line 400, in finalize_response
    % type(response)
AssertionError: Expected a `Response`, `HttpResponse` or `HttpStreamingResponse` to be returned from the view, but received a `<class 'NoneType'>`
2018-08-16 15:56:22,623 - base.py[line:152] - WARNING: Not Found: /saltstack/api/minions/
